Workbook

Sheet SP1
A1: Div | B1: Date | C1: Time | D1: HomeTeam | E1: AwayTeam | F1: FTHG | G1: FTAG | H1: FTR | I1: HTHG | J1: HTAG | K1: HTR | L1: HS | M1: AS | N1: HST | O1: AST | P1: HF | Q1: AF | R1: HC | S1: AC | T1: HY | U1: AY | V1: HR | W1: AR | X1: B365H | Y1: B365D | Z1: B365A | AA1: BFDH | AB1: BFDD | AC1: BFDA | AD1: BMGMH | AE1: BMGMD | AF1: BMGMA | AG1: BVH | AH1: BVD | AI1: BVA | AJ1: BWH | AK1: BWD | AL1: BWA | AM1: CLH | AN1: CLD | AO1: CLA | AP1: LBH | AQ1: LBD | AR1: LBA | AS1: PSH | AT1: PSD | AU1: PSA | AV1: MaxH | AW1: MaxD | AX1: MaxA | AY1: AvgH | AZ1: AvgD | BA1: AvgA | BB1: BFEH | BC1: BFED | BD1: BFEA | BE1: B365>2.5 | BF1: B365<2.5 | BG1: P>2.5 | BH1: P<2.5 | BI1: Max>2.5 | BJ1: Max<2.5 | BK1: Avg>2.5 | BL1: Avg<2.5 | BM1: BFE>2.5 | BN1: BFE<2.5 | BO1: AHh | BP1: B365AHH | BQ1: B365AHA | BR1: PAHH | BS1: PAHA | BT1: MaxAHH | BU1: MaxAHA | BV1: AvgAHH | BW1: AvgAHA | BX1: BFEAHH | BY1: BFEAHA | BZ1: B365CH | CA1: B365CD | CB1: B365CA | CC1: BFDCH | CD1: BFDCD | CE1: BFDCA | CF1: BMGMCH | CG1: BMGMCD | CH1: BMGMCA | CI1: BVCH | CJ1: BVCD | CK1: BVCA | CL1: BWCH | CM1: BWCD | CN1: BWCA | CO1: CLCH | CP1: CLCD | CQ1: CLCA | CR1: LBCH | CS1: LBCD | CT1: LBCA | CU1: PSCH | CV1: PSCD | CW1: PSCA | CX1: MaxCH | CY1: MaxCD | CZ1: MaxCA | DA1: AvgCH | DB1: AvgCD | DC1: AvgCA | DD1: BFECH | DE1: BFECD | DF1: BFECA | DG1: B365C>2.5 | DH1: B365C<2.5 | DI1: PC>2.5 | DJ1: PC<2.5 | DK1: MaxC>2.5 | DL1: MaxC<2.5 | DM1: AvgC>2.5 | DN1: AvgC<2.5 | DO1: BFEC>2.5 | DP1: BFEC<2.5 | DQ1: AHCh | DR1: B365CAHH | DS1: B365CAHA | DT1: PCAHH | DU1: PCAHA | DV1: MaxCAHH | DW1: MaxCAHA | DX1: AvgCAHH | DY1: AvgCAHA | DZ1: BFECAHH | EA1: BFECAHA
A2: SP1 | B2: 2025-08-15 | C2: 18:00:00.000 | D2: Girona | E2: Vallecano | F2: 1 | G2: 3 | H2: A | I2: 0 | J2: 3 | K2: A | L2: 7 | M2: 16 | N2: 2 | O2: 5 | P2: 8 | Q2: 17 | R2: 2 | S2: 4 | T2: 0 | U2: 1 | V2: 1 | W2: 0 | X2: 2.25 | Y2: 3.25 | Z2: 3.3 | AA2: 2.3 | AB2: 3.2 | AC2: 3.25 | AD2: 2.17 | AE2: 3.25 | AF2: 3.25 | AG2: 2.25 | AH2: 3.3 | AI2: 3.25 | AJ2: 2.25 | AK2: 3.25 | AL2: 3.25 | AM2: 2.25 | AN2: 3.3 | AO2: 3.25 | AP2: 2.25 | AQ2: 3.25 | AR2: 3.2 | AS2: 2.3 | AT2: 3.3 | AU2: 3.45 | AV2: 2.3 | AW2: 3.33 | AX2: 3.35 | AY2: 2.24 | AZ2: 3.26 | BA2: 3.26 | BB2: 2.34 | BC2: 3.4 | BD2: 3.5 | BE2: 2.2 | BF2: 1.67 | BG2: 2.24 | BH2: 1.71 | BI2: 2.2 | BJ2: 1.73 | BK2: 2.14 | BL2: 1.68 | BM2: 2.26 | BN2: 1.78 | BO2: -0.25 | BP2: 1.98 | BQ2: 1.88 | BR2: 1.97 | BS2: 1.95 | BT2: 1.98 | BU2: 1.91 | BV2: 1.84 | BW2: 1.85 | BX2: 1.99 | BY2: 1.98 | BZ2: 2.45 | CA2: 3.2 | CB2: 3.1 | CC2: 2.4 | CD2: 3.2 | CE2: 3.1 | CF2: 2.33 | CG2: 3 | CH2: 3.1 | CI2: 2.4 | CJ2: 3.25 | CK2: 3 | CL2: 2.35 | CM2: 3.2 | CN2: 3.1 | CO2: 2.37 | CP2: 3.2 | CQ2: 3.1 | CR2: 2.37 | CS2: 3.2 | CT2: 3.1 | CU2: 2.29 | CV2: 3.32 | CW2: 3.45 | CX2: 2.45 | CY2: 3.25 | CZ2: 3.15 | DA2: 2.39 | DB2: 3.15 | DC2: 3.09 | DD2: 2.5 | DE2: 3.25 | DF2: 3.35 | DG2: 2.2 | DH2: 1.67 | DI2: 2.24 | DJ2: 1.72 | DK2: 2.22 | DL2: 1.68 | DM2: 2.17 | DN2: 1.66 | DO2: 2.36 | DP2: 1.72 | DQ2: -0.25 | DR2: 2.1 | DS2: 1.78 | DT2: 1.97 | DU2: 1.95 | DV2: 2.1 | DW2: 1.8 | DX2: 1.95 | DY2: 1.75 | DZ2: 2.11 | EA2: 1.89
A3: SP1 | B3: 2025-08-15 | C3: 20:29:59.9999999999968050 | D3: Villarreal | E3: Oviedo | F3: 2 | G3: 0 | H3: H | I3: 2 | J3: 0 | K3: H | L3: 25 | M3: 5 | N3: 10 | O3: 4 | P3: 10 | Q3: 8 | R3: 10 | S3: 1 | T3: 1 | U3: 2 | V3: 0 | W3: 1 | X3: 1.4 | Y3: 4.75 | Z3: 8 | AA3: 1.4 | AB3: 4.5 | AC3: 8.5 | AD3: 1.34 | AE3: 5 | AF3: 7.5 | AG3: 1.36 | AH3: 4.75 | AI3: 8.5 | AJ3: 1.4 | AK3: 4.6 | AL3: 8 | AM3: 1.4 | AN3: 4.6 | AO3: 8 | AP3: 1.4 | AQ3: 4.6 | AR3: 8 | AS3: 1.41 | AT3: 4.76 | AU3: 8.8 | AV3: 1.4 | AW3: 5.1 | AX3: 8.5 | AY3: 1.38 | AZ3: 4.74 | BA3: 8.11 | BB3: 1.41 | BC3: 5.1 | BD3: 9.6 | BE3: 1.85 | BF3: 2 | BG3: 1.89 | BH3: 2.02 | BI3: 1.91 | BJ3: 2 | BK3: 1.84 | BL3: 1.92 | BM3: 1.95 | BN3: 2.02 | BO3: -1.25 | BP3: 1.88 | BQ3: 1.98 | BR3: 1.96 | BS3: 1.96 | BT3: 1.9 | BU3: 1.98 | BV3: 1.81 | BW3: 1.88 | BX3: 1.96 | BY3: 2 | BZ3: 1.4 | CA3: 4.75 | CB3: 8 | CC3: 1.36 | CD3: 4.6 | CE3: 9 | CF3: 1.37 | CG3: 4.8 | CH3: 7.5 | CI3: 1.36 | CJ3: 4.75 | CK3: 9 | CL3: 1.41 | CM3: 4.6 | CN3: 7.75 | CO3: 1.4 | CP3: 4.6 | CQ3: 8 | CR3: 1.4 | CS3: 4.5 | CT3: 7.5 | CU3: 1.4 | CV3: 4.87 | CW3: 8.96 | CX3: 1.42 | CY3: 4.9 | CZ3: 9 | DA3: 1.39 | DB3: 4.7 | DC3: 8.02 | DD3: 1.41 | DE3: 5.2 | DF3: 9.6 | DG3: 1.83 | DH3: 2.03 | DI3: 1.85 | DJ3: 2.06 | DK3: 1.89 | DL3: 2.03 | DM3: 1.82 | DN3: 1.94 | DO3: 1.9 | DP3: 2.06 | DQ3: -1.25 | DR3: 1.9 | DS3: 1.95 | DT3: 1.93 | DU3: 2 | DV3: 1.94 | DW3: 1.96 | DX3: 1.82 | DY3: 1.87 | DZ3: 1.96 | EA3: 2.02
A4: SP1 | B4: 2025-08-16 | C4: 18:30:00.0000000000031950 | D4: Mallorca | E4: Barcelona | F4: 0 | G4: 3 | H4: A | I4: 0 | J4: 2 | K4: A | L4: 4 | M4: 24 | N4: 1 | O4: 8 | P4: 8 | Q4: 17 | R4: 3 | S4: 6 | T4: 4 | U4: 1 | V4: 2 | W4: 0 | X4: 7 | Y4: 5 | Z4: 1.4 | AA4: 7 | AB4: 4.6 | AC4: 1.44 | AD4: 7 | AE4: 4.9 | AF4: 1.38 | AG4: 7 | AH4: 4.6 | AI4: 1.44 | AJ4: 6.5 | AK4: 4.75 | AL4: 1.46 | AM4: 6.5 | AN4: 4.6 | AO4: 1.44 | AP4: 6.5 | AQ4: 4.6 | AR4: 1.44 | AS4: 6.68 | AT4: 5.03 | AU4: 1.45 | AV4: 7 | AW4: 5 | AX4: 1.48 | AY4: 6.75 | AZ4: 4.74 | BA4: 1.43 | BB4: 7.8 | BC4: 5.2 | BD4: 1.47 | BE4: 1.62 | BF4: 2.3 | BG4: 1.64 | BH4: 2.35 | BI4: 1.62 | BJ4: 2.35 | BK4: 1.6 | BL4: 2.25 | BM4: 1.66 | BN4: 2.46 | BO4: 1.25 | BP4: 1.88 | BQ4: 1.98 | BR4: 1.9 | BS4: 2.01 | BT4: 1.88 | BU4: 1.98 | BV4: 1.83 | BW4: 1.85 | BX4: 1.95 | BY4: 1.99 | BZ4: 9.5 | CA4: 5.5 | CB4: 1.3 | CC4: 9.5 | CD4: 6 | CE4: 1.29 | CF4: 8.5 | CG4: 5.5 | CH4: 1.29 | CI4: 9 | CJ4: 6 | CK4: 1.29 | CL4: 8.75 | CM4: 5.75 | CN4: 1.31 | CO4: 8.5 | CP4: 5.75 | CQ4: 1.3 | CR4: 8.5 | CS4: 5.5 | CT4: 1.3 | CU4: 8.06 | CV4: 5.31 | CW4: 1.39 | CX4: 9.5 | CY4: 7.8 | CZ4: 5.4 | DA4: 8.7 | DB4: 5.79 | DC4: 1.56 | DD4: 10 | DE4: 5.8 | DF4: 1.37 | DG4: 1.44 | DH4: 2.75 | DI4: 1.5 | DJ4: 2.71 | DK4: 1.47 | DL4: 2.9 | DM4: 1.43 | DN4: 2.72 | DO4: 1.49 | DP4: 2.98 | DQ4: 1.5 | DR4: 2 | DS4: 1.85 | DT4: 1.88 | DU4: 2.05 | DV4: 2 | DW4: 1.93 | DX4: 1.9 | DY4: 1.86 | DZ4: 2.04 | EA4: 1.94
A5: SP1 | B5: 2025-08-16 | C5: 20:29:59.9999999999968050 | D5: Alaves | E5: Levante | F5: 2 | G5: 1 | H5: H | I5: 1 | J5: 0 | K5: H | L5: 15 | M5: 7 | N5: 4 | O5: 3 | P5: 15 | Q5: 13 | R5: 10 | S5: 1 | T5: 0 | U5: 1 | V5: 0 | W5: 0 | X5: 2.15 | Y5: 3 | Z5: 3.8 | AA5: 2.2 | AB5: 3 | AC5: 3.75 | AD5: 2.16 | AE5: 3.05 | AF5: 3.55 | AG5: 2.15 | AH5: 3.1 | AI5: 3.7 | AJ5: 2.25 | AK5: 3 | AL5: 3.5 | AM5: 2.25 | AN5: 3 | AO5: 3.5 | AP5: 2.25 | AQ5: 3 | AR5: 3.5 | AS5: 2.18 | AT5: 3.18 | AU5: 3.84 | AV5: 2.25 | AW5: 3.1 | AX5: 3.8 | AY5: 2.19 | AZ5: 3.04 | BA5: 3.64 | BB5: 2.28 | BC5: 3.2 | BD5: 3.95 | BE5: 2.63 | BF5: 1.5 | BG5: 2.77 | BH5: 1.48 | BI5: 2.7 | BJ5: 1.5 | BK5: 2.58 | BL5: 1.47 | BM5: 2.78 | BN5: 1.52 | BO5: -0.25 | BP5: 1.83 | BQ5: 2.03 | BR5: 1.85 | BS5: 2.06 | BT5: 1.86 | BU5: 2.03 | BV5: 1.78 | BW5: 1.91 | BX5: 1.92 | BY5: 2.07 | BZ5: 2.1 | CA5: 3.1 | CB5: 3.9 | CC5: 2.1 | CD5: 3.1 | CE5: 4 | CF5: 2.08 | CG5: 2.95 | CH5: 3.85 | CI5: 2.05 | CJ5: 3.13 | CK5: 4 | CL5: 2.05 | CM5: 3.1 | CN5: 3.9 | CO5: 2.1 | CP5: 3.1 | CQ5: 3.8 | CR5: 2.05 | CS5: 3.1 | CT5: 3.9 | CU5: 2.19 | CV5: 3.14 | CW5: 3.93 | CX5: 2.12 | CY5: 3.15 | CZ5: 4 | DA5: 2.08 | DB5: 3.08 | DC5: 3.92 | DD5: 2.14 | DE5: 3.25 | DF5: 4.3 | DG5: 2.63 | DH5: 1.5 | DI5: 2.54 | DJ5: 1.57 | DK5: 2.63 | DL5: 1.54 | DM5: 2.51 | DN5: 1.5 | DO5: 2.66 | DP5: 1.59 | DQ5: -0.25 | DR5: 1.8 | DS5: 2.05 | DT5: 1.86 | DU5: 2.07 | DV5: 1.8 | DW5: 2.07 | DX5: 1.7 | DY5: 2 | DZ5: 1.81 | EA5: 2.2
A6: SP1 | B6: 2025-08-16 | C6: 20:29:59.9999999999968050 | D6: Valencia | E6: Sociedad | F6: 1 | G6: 1 | H6: D | I6: 0 | J6: 0 | K6: D | L6: 18 | M6: 13 | N6: 2 | O6: 3 | P6: 5 | Q6: 11 | R6: 8 | S6: 7 | T6: 1 | U6: 2 | V6: 0 | W6: 0 | X6: 2.6 | Y6: 2.9 | Z6: 3.1 | AA6: 2.5 | AB6: 2.88 | AC6: 3.2 | AD6: 2.5 | AE6: 2.85 | AF6: 3 | AG6: 2.55 | AH6: 2.9 | AI6: 3.1 | AJ6: 2.55 | AK6: 2.95 | AL6: 3 | AM6: 2.6 | AN6: 3 | AO6: 3 | AP6: 2.5 | AQ6: 2.9 | AR6: 3 | AS6: 2.65 | AT6: 2.89 | AU6: 3.23 | AV6: 2.6 | AW6: 3 | AX6: 3.2 | AY6: 2.55 | AZ6: 2.89 | BA6: 3.07 | BB6: 2.74 | BC6: 2.98 | BD6: 3.3 | BE6: 2.75 | BF6: 1.44 | BG6: 2.85 | BH6: 1.44 | BI6: 3.05 | BJ6: 1.45 | BK6: 2.76 | BL6: 1.41 | BM6: 2.94 | BN6: 1.48 | BO6: 0 | BP6: 1.75 | BQ6: 2.13 | BR6: 1.78 | BS6: 2.17 | BT6: 1.8 | BU6: 2.13 | BV6: 1.74 | BW6: 2.01 | BX6: 1.82 | BY6: 2.19 | BZ6: 2.45 | CA6: 3 | CB6: 3.2 | CC6: 2.4 | CD6: 3 | CE6: 3.2 | CF6: 2.38 | CG6: 2.95 | CH6: 3.15 | CI6: 2.45 | CJ6: 3.1 | CK6: 3.1 | CL6: 2.45 | CM6: 2.95 | CN6: 3.2 | CO6: 2.45 | CP6: 3 | CQ6: 3.2 | CR6: 2.45 | CS6: 2.9 | CT6: 3.1 | CU6: 2.53 | CV6: 3.04 | CW6: 3.3 | CX6: 2.49 | CY6: 3.1 | CZ6: 3.25 | DA6: 2.43 | DB6: 3 | DC6: 3.18 | DD6: 2.58 | DE6: 3.1 | DF6: 3.35 | DG6: 2.63 | DH6: 1.5 | DI6: 2.55 | DJ6: 1.56 | DK6: 2.63 | DL6: 1.55 | DM6: 2.49 | DN6: 1.51 | DO6: 2.68 | DP6: 1.57 | DQ6: -0.25 | DR6: 2.1 | DS6: 1.78 | DT6: 2.13 | DU6: 1.81 | DV6: 2.1 | DW6: 1.78 | DX6: 1.96 | DY6: 1.74 | DZ6: 2.18 | EA6: 1.84
A7: SP1 | B7: 2025-08-17 | C7: 15:59:59.9999999999968050 | D7: Celta | E7: Getafe | F7: 0 | G7: 2 | H7: A | I7: 0 | J7: 0 | K7: D | L7: 11 | M7: 10 | N7: 3 | O7: 3 | P7: 15 | Q7: 17 | R7: 9 | S7: 3 | T7: 3 | U7: 2 | V7: 0 | W7: 0 | X7: 1.73 | Y7: 3.5 | Z7: 5.25 | AA7: 1.73 | AB7: 3.4 | AC7: 5.5 | AD7: 1.65 | AE7: 3.6 | AF7: 5.2 | AG7: 1.7 | AH7: 3.3 | AI7: 5 | AJ7: 1.72 | AK7: 3.5 | AL7: 5.25 | AM7: 1.73 | AN7: 3.5 | AO7: 5.25 | AP7: 1.7 | AQ7: 3.5 | AR7: 5.25 | AS7: 1.76 | AT7: 3.43 | AU7: 5.71 | AV7: 1.75 | AW7: 3.65 | AX7: 5.66 | AY7: 1.71 | AZ7: 3.48 | BA7: 5.25 | BB7: 1.77 | BC7: 3.65 | BD7: 5.8 | BE7: 2.38 | BF7: 1.57 | BG7: 2.5 | BH7: 1.57 | BI7: 2.4 | BJ7: 1.58 | BK7: 2.36 | BL7: 1.54 | BM7: 2.52 | BN7: 1.62 | BO7: -0.75 | BP7: 1.98 | BQ7: 1.88 | BR7: 2.01 | BS7: 1.9 | BT7: 1.98 | BU7: 1.9 | BV7: 1.89 | BW7: 1.8 | BX7: 2.01 | BY7: 1.93 | BZ7: 1.67 | CA7: 3.5 | CB7: 5.75 | CC7: 1.67 | CD7: 3.4 | CE7: 6 | CF7: 1.63 | CG7: 3.5 | CH7: 5.6 | CI7: 1.67 | CJ7: 3.5 | CK7: 6 | CL7: 1.7 | CM7: 3.4 | CN7: 5.75 | CO7: 1.7 | CP7: 3.4 | CQ7: 5.75 | CR7: 1.7 | CS7: 3.4 | CT7: 5.75 | CU7: 1.61 | CV7: 3.73 | CW7: 7.04 | CX7: 1.7 | CY7: 3.55 | CZ7: 6 | DA7: 1.67 | DB7: 3.48 | DC7: 5.81 | DD7: 1.75 | DE7: 3.6 | DF7: 6.4 | DG7: 2.63 | DH7: 1.5 | DI7: 2.49 | DJ7: 1.58 | DK7: 2.63 | DL7: 1.55 | DM7: 2.49 | DN7: 1.51 | DO7: 2.68 | DP7: 1.57 | DQ7: -0.75 | DR7: 1.93 | DS7: 1.93 | DT7: 1.81 | DU7: 2.15 | DV7: 1.93 | DW7: 1.95 | DX7: 1.85 | DY7: 1.84 | DZ7: 2 | EA7: 1.99
A8: SP1 | B8: 2025-08-17 | C8: 18:30:00.0000000000031950 | D8: Ath Bilbao | E8: Sevilla | F8: 3 | G8: 2 | H8: H | I8: 2 | J8: 0 | K8: H | L8: 14 | M8: 12 | N8: 3 | O8: 6 | P8: 8 | Q8: 12 | R8: 10 | S8: 1 | T8: 0 | U8: 2 | V8: 0 | W8: 0 | X8: 1.57 | Y8: 3.9 | Z8: 6 | AA8: 1.57 | AB8: 3.75 | AC8: 6.5 | AD8: 1.47 | AE8: 4.1 | AF8: 6.75 | AG8: 1.53 | AH8: 3.7 | AI8: 5.75 | AJ8: 1.6 | AK8: 3.8 | AL8: 6 | AM8: 1.6 | AN8: 3.8 | AO8: 6 | AP8: 1.6 | AQ8: 3.8 | AR8: 5.75 | AS8: 1.6 | AT8: 4.05 | AU8: 6.12 | AV8: 1.6 | AW8: 4.2 | AX8: 6.75 | AY8: 1.55 | AZ8: 3.91 | BA8: 6.17 | BB8: 1.61 | BC8: 4 | BD8: 6.8 | BE8: 2.1 | BF8: 1.73 | BG8: 2.11 | BH8: 1.78 | BI8: 2.1 | BJ8: 1.74 | BK8: 2.07 | BL8: 1.71 | BM8: 2.18 | BN8: 1.81 | BO8: -1 | BP8: 2.05 | BQ8: 1.8 | BR8: 2.08 | BS8: 1.84 | BT8: 2.05 | BU8: 1.85 | BV8: 1.91 | BW8: 1.8 | BX8: 2.07 | BY8: 1.86 | BZ8: 1.53 | CA8: 3.8 | CB8: 6.5 | CC8: 1.57 | CD8: 3.75 | CE8: 6.5 | CF8: 1.53 | CG8: 3.8 | CH8: 6.25 | CI8: 1.55 | CJ8: 3.9 | CK8: 6.5 | CL8: 1.58 | CM8: 3.7 | CN8: 6.5 | CO8: 1.57 | CP8: 3.75 | CQ8: 6.5 | CR8: 1.57 | CS8: 3.7 | CT8: 6.5 | CU8: 1.67 | CV8: 3.69 | CW8: 6.24 | CX8: 1.59 | CY8: 3.9 | CZ8: 6.6 | DA8: 1.56 | DB8: 3.8 | DC8: 6.43 | DD8: 1.62 | DE8: 4 | DF8: 7.2 | DG8: 2.2 | DH8: 1.67 | DI8: 2.31 | DJ8: 1.67 | DK8: 2.25 | DL8: 1.67 | DM8: 2.2 | DN8: 1.64 | DO8: 2.28 | DP8: 1.75 | DQ8: -1 | DR8: 2 | DS8: 1.85 | DT8: 2.25 | DU8: 1.72 | DV8: 2.04 | DW8: 1.85 | DX8: 1.96 | DY8: 1.76 | DZ8: 2.11 | EA8: 1.88
A9: SP1 | B9: 2025-08-17 | C9: 20:29:59.9999999999968050 | D9: Espanol | E9: Ath Madrid | F9: 2 | G9: 1 | H9: H | I9: 0 | J9: 1 | K9: A | L9: 10 | M9: 15 | N9: 5 | O9: 4 | P9: 14 | Q9: 11 | R9: 1 | S9: 3 | T9: 3 | U9: 3 | V9: 0 | W9: 0 | X9: 6 | Y9: 3.9 | Z9: 1.57 | AA9: 6.5 | AB9: 3.75 | AC9: 1.57 | AD9: 6.1 | AE9: 4 | AF9: 1.52 | AG9: 6 | AH9: 3.6 | AI9: 1.53 | AJ9: 6.5 | AK9: 4 | AL9: 1.53 | AM9: 6.5 | AN9: 4 | AO9: 1.53 | AP9: 6.5 | AQ9: 4 | AR9: 1.53 | AS9: 6.57 | AT9: 3.86 | AU9: 1.6 | AV9: 6.66 | AW9: 4 | AX9: 1.6 | AY9: 6.25 | AZ9: 3.86 | BA9: 1.55 | BB9: 7.2 | BC9: 4 | BD9: 1.62 | BE9: 2.2 | BF9: 1.67 | BG9: 2.28 | BH9: 1.68 | BI9: 2.2 | BJ9: 1.72 | BK9: 2.14 | BL9: 1.66 | BM9: 2.32 | BN9: 1.72 | BO9: 1 | BP9: 1.8 | BQ9: 2.05 | BR9: 1.83 | BS9: 2.1 | BT9: 1.8 | BU9: 2.05 | BV9: 1.77 | BW9: 1.94 | BX9: 1.86 | BY9: 2.09 | BZ9: 5.5 | CA9: 3.9 | CB9: 1.62 | CC9: 6 | CD9: 3.75 | CE9: 1.6 | CF9: 5.6 | CG9: 3.9 | CH9: 1.56 | CI9: 5.75 | CJ9: 3.9 | CK9: 1.6 | CL9: 5.75 | CM9: 3.8 | CN9: 1.62 | CO9: 5.75 | CP9: 3.8 | CQ9: 1.61 | CR9: 5.5 | CS9: 3.8 | CT9: 1.61 | CU9: 5.8 | CV9: 3.89 | CW9: 1.66 | CX9: 6.2 | CY9: 4 | CZ9: 1.65 | DA9: 5.7 | DB9: 3.86 | DC9: 1.6 | DD9: 6.2 | DE9: 4.1 | DF9: 1.66 | DG9: 2 | DH9: 1.85 | DI9: 1.97 | DJ9: 1.93 | DK9: 2 | DL9: 1.89 | DM9: 1.94 | DN9: 1.82 | DO9: 2.02 | DP9: 1.96 | DQ9: 1 | DR9: 1.73 | DS9: 2.08 | DT9: 1.76 | DU9: 2.17 | DV9: 1.83 | DW9: 2.09 | DX9: 1.73 | DY9: 2 | DZ9: 1.81 | EA9: 2.18
A10: SP1 | B10: 2025-08-18 | C10: 20:00:00.0000000000031950 | D10: Elche | E10: Betis | F10: 1 | G10: 1 | H10: D | I10: 0 | J10: 1 | K10: A | L10: 6 | M10: 12 | N10: 2 | O10: 4 | P10: 14 | Q10: 13 | R10: 1 | S10: 3 | T10: 0 | U10: 1 | V10: 0 | W10: 0 | X10: 3.4 | Y10: 3.3 | Z10: 2.2 | AA10: 3.4 | AB10: 3.25 | AC10: 2.2 | AD10: 3.2 | AE10: 3.3 | AF10: 2.17 | AG10: 3.25 | AH10: 3.2 | AI10: 2.1 | AJ10: 3.4 | AK10: 3.25 | AL10: 2.2 | AM10: 3.4 | AN10: 3.25 | AO10: 2.2 | AP10: 3.4 | AQ10: 3.25 | AR10: 2.15 | AS10: 3.45 | AT10: 3.43 | AU10: 2.21 | AV10: 3.4 | AW10: 3.4 | AX10: 2.2 | AY10: 3.33 | AZ10: 3.27 | BA10: 2.17 | BB10: 3.55 | BC10: 3.4 | BD10: 2.28 | BE10: 2.2 | BF10: 1.67 | BG10: 2.21 | BH10: 1.72 | BI10: 2.2 | BJ10: 1.76 | BK10: 2.08 | BL10: 1.7 | BM10: 2.24 | BN10: 1.77 | BO10: 0.25 | BP10: 1.98 | BQ10: 1.88 | BR10: 2 | BS10: 1.91 | BT10: 1.98 | BU10: 1.88 | BV10: 1.88 | BW10: 1.76 | BX10: 2 | BY10: 1.94 | BZ10: 3.2 | CA10: 3.25 | CB10: 2.3 | CC10: 3.2 | CD10: 3.2 | CE10: 2.3 | CF10: 3.2 | CG10: 3.15 | CH10: 2.25 | CI10: 3.2 | CJ10: 3.25 | CK10: 2.3 | CL10: 3.2 | CM10: 3.2 | CN10: 2.35 | CO10: 3.2 | CP10: 3.2 | CQ10: 2.3 | CR10: 3.2 | CS10: 3.1 | CT10: 2.3 | CU10: 3.34 | CV10: 3.22 | CW10: 2.4 | CX10: 3.25 | CY10: 3.25 | CZ10: 2.36 | DA10: 3.2 | DB10: 3.19 | DC10: 2.3 | DD10: 3.45 | DE10: 3.3 | DF10: 2.4 | DG10: 2.2 | DH10: 1.67 | DI10: 2.3 | DJ10: 1.68 | DK10: 2.25 | DL10: 1.73 | DM10: 2.16 | DN10: 1.66 | DO10: 2.32 | DP10: 1.73 | DQ10: 0.25 | DR10: 1.88 | DS10: 1.98 | DT10: 1.88 | DU10: 2.04 | DV10: 1.88 | DW10: 2 | DX10: 1.81 | DY10: 1.84 | DZ10: 1.94 | EA10: 2.04
A11: SP1 | B11: 2025-08-19 | C11: 20:00:00.0000000000031950 | D11: Real Madrid | E11: Osasuna | F11: 1 | G11: 0 | H11: H | I11: 0 | J11: 0 | K11: D | L11: 18 | M11: 2 | N11: 5 | O11: 0 | P11: 10 | Q11: 12 | R11: 7 | S11: 0 | T11: 1 | U11: 0 | V11: 0 | W11: 1 | X11: 1.22 | Y11: 6.25 | Z11: 13 | AA11: 1.2 | AB11: 6.5 | AC11: 15 | AD11: 1.17 | AE11: 7 | AF11: 13 | AG11: 1.2 | AH11: 6.5 | AI11: 13 | AJ11: 1.22 | AK11: 6.5 | AL11: 13 | AM11: 1.22 | AN11: 6.5 | AO11: 13 | AP11: 1.22 | AQ11: 6.5 | AR11: 13 | AS11: 1.23 | AT11: 6.99 | AU11: 12.34 | AV11: 1.23 | AW11: 7 | AX11: 15 | AY11: 1.2 | AZ11: 6.66 | BA11: 13.16 | BB11: 1.23 | BC11: 7.8 | BD11: 16.5 | BE11: 1.5 | BF11: 2.63 | BG11: 1.52 | BH11: 2.6 | BI11: 1.52 | BJ11: 2.63 | BK11: 1.49 | BL11: 2.56 | BM11: 1.56 | BN11: 2.72 | BO11: -2 | BP11: 2.03 | BQ11: 1.78 | BR11: 2.14 | BS11: 1.76 | BT11: 2.05 | BU11: 1.81 | BV11: 1.97 | BW11: 1.75 | BX11: 2.15 | BY11: 1.83 | BZ11: 1.22 | CA11: 7 | CB11: 11 | CC11: 1.22 | CD11: 6.5 | CE11: 13 | CF11: 1.18 | CG11: 6.5 | CH11: 13 | CI11: 1.2 | CJ11: 7 | CK11: 13 | CL11: 1.22 | CM11: 6.75 | CN11: 12 | CO11: 1.22 | CP11: 7 | CQ11: 11 | CR11: 1.22 | CS11: 6.5 | CT11: 12 | CU11: 1.22 | CV11: 7.32 | CW11: 12.82 | CX11: 1.24 | CY11: 7 | CZ11: 13 | DA11: 1.21 | DB11: 6.67 | DC11: 12.34 | DD11: 1.24 | DE11: 7.4 | DF11: 15 | DG11: 1.44 | DH11: 2.75 | DI11: 1.47 | DJ11: 2.73 | DK11: 1.46 | DL11: 2.8 | DM11: 1.44 | DN11: 2.68 | DO11: 1.48 | DP11: 3.05 | DQ11: -2 | DR11: 2.03 | DS11: 1.78 | DT11: 2.07 | DU11: 1.85 | DV11: 2.07 | DW11: 1.83 | DX11: 1.97 | DY11: 1.75 | DZ11: 2.14 | EA11: 1.86
A12: SP1 | B12: 2025-08-22 | C12: 20:29:59.9999999999968050 | D12: Betis | E12: Alaves | F12: 1 | G12: 0 | H12: H | I12: 1 | J12: 0 | K12: H | L12: 16 | M12: 11 | N12: 5 | O12: 5 | P12: 10 | Q12: 17 | R12: 5 | S12: 2 | T12: 2 | U12: 3 | V12: 0 | W12: 0 | X12: 1.91 | Y12: 3.4 | Z12: 4.2 | AA12: 1.9 | AB12: 3.3 | AC12: 4.5 | AD12: 1.82 | AE12: 3.35 | AF12: 4.4 | AG12: 1.9 | AH12: 3.4 | AI12: 4.33 | AJ12: 1.87 | AK12: 3.4 | AL12: 4.33 | AM12: 1.85 | AN12: 3.4 | AO12: 4.33 | AP12: 1.85 | AQ12: 3.4 | AR12: 4.33 | AS12: 1.92 | AT12: 3.45 | AU12: 4.6 | AV12: 1.91 | AW12: 3.5 | AX12: 4.5 | AY12: 1.88 | AZ12: 3.38 | BA12: 4.37 | BB12: 1.95 | BC12: 3.5 | BD12: 4.8 | BE12: 2.2 | BF12: 1.67 | BG12: 2.33 | BH12: 1.67 | BI12: 2.3 | BJ12: 1.67 | BK12: 2.23 | BL12: 1.62 | BM12: 2.36 | BN12: 1.71 | BO12: -0.5 | BP12: 1.9 | BQ12: 1.95 | BR12: 1.93 | BS12: 2 | BT12: 1.9 | BU12: 1.96 | BV12: 1.84 | BW12: 1.91 | BX12: 1.96 | BY12: 2.02 | BZ12: 1.83 | CA12: 3.4 | CB12: 4.5 | CC12: 1.83 | CD12: 3.4 | CE12: 4.6 | CF12: 1.84 | CG12: 3.35 | CH12: 4.3 | CI12: 1.83 | CJ12: 3.4 | CK12: 4.6 | CL12: 1.85 | CM12: 3.4 | CN12: 4.5 | CO12: 1.85 | CP12: 3.4 | CQ12: 4.5 | CR12: 1.85 | CS12: 3.4 | CT12: 4.4 | CU12: 1.97 | CV12: 3.38 | CW12: 4.43 | CX12: 1.86 | CY12: 3.5 | CZ12: 4.6 | DA12: 1.84 | DB12: 3.4 | DC12: 4.47 | DD12: 1.91 | DE12: 3.6 | DF12: 5 | DG12: 2.2 | DH12: 1.67 | DI12: 2.36 | DJ12: 1.65 | DK12: 2.25 | DL12: 1.67 | DM12: 2.21 | DN12: 1.63 | DO12: 2.36 | DP12: 1.72 | DQ12: -0.5 | DR12: 1.83 | DS12: 2.03 | DT12: 1.98 | DU12: 1.94 | DV12: 1.87 | DW12: 2.03 | DX12: 1.82 | DY12: 1.93 | DZ12: 1.91 | EA12: 2.09
A13: SP1 | B13: 2025-08-23 | C13: 15:59:59.9999999999968050 | D13: Mallorca | E13: Celta | F13: 1 | G13: 1 | H13: D | I13: 0 | J13: 1 | K13: A | L13: 12 | M13: 8 | N13: 4 | O13: 2 | P13: 12 | Q13: 12 | R13: 3 | S13: 4 | T13: 3 | U13: 3 | V13: 0 | W13: 0 | X13: 3 | Y13: 3.1 | Z13: 2.55 | AA13: 3 | AB13: 3.1 | AC13: 2.5 | AD13: 2.9 | AE13: 3.1 | AF13: 2.45 | AG13: 2.9 | AH13: 3.13 | AI13: 2.55 | AJ13: 2.95 | AK13: 3.1 | AL13: 2.5 | AM13: 2.9 | AN13: 3.1 | AO13: 2.5 | AP13: 2.9 | AQ13: 3.1 | AR13: 2.5 | AS13: 3.06 | AT13: 3.1 | AU13: 2.6 | AV13: 3 | AW13: 3.15 | AX13: 2.6 | AY13: 2.94 | AZ13: 3.09 | BA13: 2.52 | BB13: 3.1 | BC13: 3.2 | BD13: 2.7 | BE13: 2.38 | BF13: 1.57 | BG13: 2.49 | BH13: 1.58 | BI13: 2.43 | BJ13: 1.6 | BK13: 2.34 | BL13: 1.55 | BM13: 2.48 | BN13: 1.63 | BO13: 0 | BP13: 2.1 | BQ13: 1.78 | BR13: 2.13 | BS13: 1.8 | BT13: 2.1 | BU13: 1.78 | BV13: 2.02 | BW13: 1.73 | BX13: 2.13 | BY13: 1.85 | BZ13: 3.3 | CA13: 3.2 | CB13: 2.3 | CC13: 3.25 | CD13: 3.2 | CE13: 2.3 | CF13: 3 | CG13: 3.2 | CH13: 2.33 | CI13: 3.13 | CJ13: 3.25 | CK13: 2.38 | CL13: 3.1 | CM13: 3.2 | CN13: 2.4 | CO13: 3.1 | CP13: 3.2 | CQ13: 2.4 | CR13: 3 | CS13: 3.2 | CT13: 2.37 | CU13: 3.26 | CV13: 3.16 | CW13: 2.48 | CX13: 3.3 | CY13: 3.3 | CZ13: 2.5 | DA13: 3.13 | DB13: 3.21 | DC13: 2.35 | DD13: 3.3 | DE13: 3.4 | DF13: 2.44 | DG13: 2.1 | DH13: 1.73 | DI13: 2.41 | DJ13: 1.63 | DK13: 2.28 | DL13: 1.73 | DM13: 2.15 | DN13: 1.67 | DO13: 2.28 | DP13: 1.77 | DQ13: 0.25 | DR13: 1.88 | DS13: 1.98 | DT13: 1.83 | DU13: 2.11 | DV13: 1.88 | DW13: 2.05 | DX13: 1.82 | DY13: 1.88 | DZ13: 1.9 | EA13: 2.09
... A83: SP1 | B83: 2025-10-18 | C83: 12:59:59.9999999999968050 | D83: Sevilla | E83: Mallorca | F83: 1 | G83: 3 | H83: A | I83: 1 | J83: 0 | K83: H | L83: 13 | M83: 7 | N83: 4 | O83: 6 | P83: 16 | Q83: 13 | R83: 9 | S83: 2 | T83: 2 | U83: 1 | V83: 0 | W83: 0 | X83: 1.85 | Y83: 3.3 | Z83: 4.75 | AA83: 1.9 | AB83: 3.4 | AC83: 4.33 | AD83: 1.81 | AE83: 3.45 | AF83: 4.7 | AG83: 1.85 | AH83: 3.4 | AI83: 4.5 | AJ83: 1.88 | AK83: 3.4 | AL83: 4.33 | AM83: 1.91 | AN83: 3.4 | AO83: 4.33 | AP83: 1.85 | AQ83: 3.3 | AR83: 4.33 | AS83: 1.87 | AT83: 3.46 | AU83: 4.74 | AV83: 1.91 | AW83: 3.5 | AX83: 4.75 | AY83: 1.85 | AZ83: 3.39 | BA83: 4.46 | BB83: 1.91 | BC83: 3.5 | BD83: 5 | BE83: 2.2 | BF83: 1.67 | BG83: 2.25 | BH83: 1.7 | BI83: 2.2 | BJ83: 1.67 | BK83: 2.17 | BL83: 1.64 | BM83: 2.3 | BN83: 1.73 | BO83: -0.5 | BP83: 1.85 | BQ83: 2 | BR83: 1.88 | BS83: 2.04 | BT83: 1.86 | BU83: 2 | BV83: 1.82 | BW83: 1.94 | BX83: 1.91 | BY83: 2.08 | BZ83: 1.85 | CA83: 3.4 | CB83: 4.5 | CC83: 1.83 | CD83: 3.5 | CE83: 4.5 | CF83: 1.79 | CG83: 3.4 | CH83: 5 | CI83: 1.83 | CJ83: 3.3 | CK83: 4.8 | CL83: 1.85 | CM83: 3.4 | CN83: 4.4 | CO83: 1.85 | CP83: 3.4 | CQ83: 4.4 | CR83: 1.85 | CS83: 3.4 | CT83: 4.33 | CU83: 1.87 | CV83: 3.49 | CW83: 4.81 | CX83: 1.91 | CY83: 3.5 | CZ83: 5 | DA83: 1.83 | DB83: 3.38 | DC83: 4.63 | DD83: 1.9 | DE83: 3.6 | DF83: 5 | DG83: 2.2 | DH83: 1.67 | DI83: 2.25 | DJ83: 1.71 | DK83: 2.22 | DL83: 1.73 | DM83: 2.15 | DN83: 1.67 | DO83: 2.26 | DP83: 1.78 | DQ83: -0.5 | DR83: 1.85 | DS83: 2 | DT83: 1.88 | DU83: 2.05 | DV83: 1.85 | DW83: 2.05 | DX83: 1.79 | DY83: 1.98 | DZ83: 1.9 | EA83: 2.09
A84: SP1 | B84: 2025-10-18 | C84: 15:14:59.9999999999968050 | D84: Barcelona | E84: Girona | F84: 2 | G84: 1 | H84: H | I84: 1 | J84: 1 | K84: D | L84: 27 | M84: 11 | N84: 9 | O84: 4 | P84: 10 | Q84: 7 | R84: 11 | S84: 5 | T84: 1 | U84: 2 | V84: 0 | W84: 0 | X84: 1.2 | Y84: 7 | Z84: 12 | AA84: 1.18 | AB84: 7.5 | AC84: 13 | AD84: 1.2 | AE84: 7 | AF84: 12.5 | AG84: 1.18 | AH84: 7.5 | AI84: 13 | AJ84: 1.19 | AK84: 8 | AL84: 12 | AM84: 1.18 | AN84: 8 | AO84: 12 | AP84: 1.18 | AQ84: 8 | AR84: 12 | AS84: 1.16 | AT84: 8.82 | AU84: 14.91 | AV84: 1.22 | AW84: 8 | AX84: 13 | AY84: 1.19 | AZ84: 7.39 | BA84: 12.16 | BB84: 1.24 | BC84: 7.8 | BD84: 14 | BE84: 1.29 | BF84: 3.75 | BI84: 1.29 | BJ84: 4 | BK84: 1.24 | BL84: 3.77 | BM84: 1.3 | BN84: 4 | BO84: -2 | BP84: 1.88 | BQ84: 1.98 | BR84: 1.75 | BS84: 2.14 | BT84: 1.88 | BU84: 2.04 | BV84: 1.78 | BW84: 1.99 | BX84: 1.9 | BY84: 2 | BZ84: 1.2 | CA84: 7 | CB84: 13 | CC84: 1.2 | CD84: 7 | CE84: 13 | CF84: 1.22 | CG84: 6.75 | CH84: 12 | CI84: 1.18 | CJ84: 7.5 | CK84: 13 | CL84: 1.22 | CM84: 7 | CN84: 12 | CO84: 1.22 | CP84: 7 | CQ84: 12 | CR84: 1.22 | CS84: 7 | CT84: 11 | CU84: 1.21 | CV84: 7.51 | CW84: 12.72 | CX84: 1.22 | CY84: 7.5 | CZ84: 13 | DA84: 1.2 | DB84: 7.02 | DC84: 11.91 | DD84: 1.21 | DE84: 8.4 | DF84: 17 | DG84: 1.3 | DH84: 3.5 | DI84: 0 | DJ84: 0 | DK84: 1.33 | DL84: 3.6 | DM84: 1.3 | DN84: 3.37 | DO84: 1.34 | DP84: 3.9 | DQ84: -2 | DR84: 1.93 | DS84: 1.93 | DT84: 1.89 | DU84: 2.01 | DV84: 1.93 | DW84: 1.95 | DX84: 1.88 | DY84: 1.91 | DZ84: 1.98 | EA84: 1.97
A85: SP1 | B85: 2025-10-18 | C85: 17:29:59.9999999999968050 | D85: Villarreal | E85: Betis | F85: 2 | G85: 2 | H85: D | I85: 1 | J85: 0 | K85: H | L85: 7 | M85: 16 | N85: 3 | O85: 3 | P85: 13 | Q85: 10 | R85: 5 | S85: 6 | T85: 1 | U85: 1 | V85: 0 | W85: 0 | X85: 1.91 | Y85: 3.6 | Z85: 4 | AA85: 1.9 | AB85: 3.75 | AC85: 3.75 | AD85: 1.87 | AE85: 3.65 | AF85: 4.1 | AG85: 1.87 | AH85: 3.8 | AI85: 3.9 | AJ85: 1.9 | AK85: 3.75 | AL85: 3.8 | AM85: 1.91 | AN85: 3.75 | AO85: 3.8 | AP85: 1.91 | AQ85: 3.75 | AR85: 3.75 | AS85: 1.93 | AT85: 3.83 | AU85: 3.91 | AV85: 1.91 | AW85: 3.8 | AX85: 4.1 | AY85: 1.88 | AZ85: 3.73 | BA85: 3.87 | BB85: 1.93 | BC85: 3.95 | BD85: 4.3 | BE85: 1.67 | BF85: 2.2 | BG85: 1.68 | BH85: 2.28 | BI85: 1.67 | BJ85: 2.2 | BK85: 1.65 | BL85: 2.16 | BM85: 1.69 | BN85: 2.36 | BO85: -0.5 | BP85: 1.88 | BQ85: 1.98 | BR85: 1.94 | BS85: 1.96 | BT85: 1.88 | BU85: 1.98 | BV85: 1.84 | BW85: 1.93 | BX85: 1.93 | BY85: 2.06 | BZ85: 2.1 | CA85: 3.6 | CB85: 3.3 | CC85: 2.05 | CD85: 3.75 | CE85: 3.3 | CF85: 2.02 | CG85: 3.65 | CH85: 3.55 | CI85: 2.1 | CJ85: 3.7 | CK85: 3.25 | CL85: 2.05 | CM85: 3.6 | CN85: 3.4 | CO85: 2.05 | CP85: 3.6 | CQ85: 3.4 | CR85: 2.05 | CS85: 3.6 | CT85: 3.3 | CU85: 2.09 | CV85: 3.65 | CW85: 3.63 | CX85: 2.1 | CY85: 3.75 | CZ85: 3.55 | DA85: 2.06 | DB85: 3.62 | DC85: 3.35 | DD85: 2.18 | DE85: 3.65 | DF85: 3.65 | DG85: 1.53 | DH85: 2.5 | DI85: 1.58 | DJ85: 2.5 | DK85: 1.55 | DL85: 2.55 | DM85: 1.53 | DN85: 2.42 | DO85: 1.62 | DP85: 2.58 | DQ85: -0.25 | DR85: 1.85 | DS85: 2 | DT85: 1.81 | DU85: 2.11 | DV85: 1.85 | DW85: 2.07 | DX85: 1.78 | DY85: 2 | DZ85: 1.88 | EA85: 2.1
A86: SP1 | B86: 2025-10-18 | C86: 20:00:00.0000000000031950 | D86: Ath Madrid | E86: Osasuna | F86: 1 | G86: 0 | H86: H | I86: 0 | J86: 0 | K86: D | L86: 18 | M86: 9 | N86: 9 | O86: 2 | P86: 10 | Q86: 11 | R86: 4 | S86: 2 | T86: 1 | U86: 3 | V86: 0 | W86: 0 | X86: 1.38 | Y86: 4.75 | Z86: 8.5 | AA86: 1.36 | AB86: 4.6 | AC86: 9.5 | AD86: 1.37 | AE86: 4.6 | AF86: 9.5 | AG86: 1.36 | AH86: 4.75 | AI86: 9 | AJ86: 1.38 | AK86: 4.75 | AL86: 8.5 | AM86: 1.36 | AN86: 4.8 | AO86: 8.5 | AP86: 1.36 | AQ86: 4.8 | AR86: 8.5 | AS86: 1.37 | AT86: 5.13 | AU86: 8.83 | AV86: 1.4 | AW86: 4.8 | AX86: 9.5 | AY86: 1.37 | AZ86: 4.68 | BA86: 8.72 | BB86: 1.4 | BC86: 5.2 | BD86: 10 | BE86: 1.88 | BF86: 1.98 | BG86: 1.89 | BH86: 1.99 | BI86: 1.91 | BJ86: 1.98 | BK86: 1.84 | BL86: 1.9 | BM86: 1.93 | BN86: 2.02 | BO86: -1.25 | BP86: 1.88 | BQ86: 1.98 | BR86: 1.85 | BS86: 2.06 | BT86: 1.88 | BU86: 1.98 | BV86: 1.83 | BW86: 1.95 | BX86: 1.91 | BY86: 2.04 | BZ86: 1.33 | CA86: 5 | CB86: 9.5 | CC86: 1.33 | CD86: 5 | CE86: 9 | CF86: 1.32 | CG86: 5 | CH86: 10 | CI86: 1.33 | CJ86: 5 | CK86: 9.5 | CL86: 1.36 | CM86: 5 | CN86: 8.5 | CO86: 1.36 | CP86: 5 | CQ86: 8.5 | CR86: 1.36 | CS86: 4.8 | CT86: 8 | CU86: 1.35 | CV86: 5.17 | CW86: 10.24 | CX86: 1.36 | CY86: 5.25 | CZ86: 10 | DA86: 1.33 | DB86: 4.98 | DC86: 9.3 | DD86: 1.36 | DE86: 5.5 | DF86: 11.5 | DG86: 1.73 | DH86: 2.1 | DI86: 1.77 | DJ86: 2.14 | DK86: 1.77 | DL86: 2.1 | DM86: 1.72 | DN86: 2.07 | DO86: 1.83 | DP86: 2.2 | DQ86: -1.5 | DR86: 2 | DS86: 1.85 | DT86: 2.12 | DU86: 1.8 | DV86: 2 | DW86: 1.86 | DX86: 1.96 | DY86: 1.81 | DZ86: 2.11 | EA86: 1.86
A87: SP1 | B87: 2025-10-19 | C87: 12:59:59.9999999999968050 | D87: Elche | E87: Ath Bilbao | F87: 0 | G87: 0 | H87: D | I87: 0 | J87: 0 | K87: D | L87: 15 | M87: 4 | N87: 5 | O87: 1 | P87: 14 | Q87: 20 | R87: 6 | S87: 2 | T87: 2 | U87: 3 | V87: 0 | W87: 0 | X87: 3.75 | Y87: 3.25 | Z87: 2.1 | AA87: 3.6 | AB87: 3.2 | AC87: 2.15 | AD87: 3.45 | AE87: 3.2 | AF87: 2.23 | AG87: 3.5 | AH87: 3.1 | AI87: 2.05 | AJ87: 3.6 | AK87: 3.25 | AL87: 2.15 | AM87: 3.6 | AN87: 3.25 | AO87: 2.15 | AP87: 3.5 | AQ87: 3.2 | AR87: 2.15 | AS87: 3.78 | AT87: 3.36 | AU87: 2.12 | AV87: 3.8 | AW87: 3.3 | AX87: 2.23 | AY87: 3.58 | AZ87: 3.2 | BA87: 2.12 | BB87: 3.9 | BC87: 3.35 | BD87: 2.22 | BE87: 2.3 | BF87: 1.62 | BG87: 2.34 | BH87: 1.65 | BI87: 2.4 | BJ87: 1.62 | BK87: 2.29 | BL87: 1.58 | BM87: 2.46 | BN87: 1.65 | BO87: 0.25 | BP87: 2.05 | BQ87: 1.8 | BR87: 2.1 | BS87: 1.83 | BT87: 2.05 | BU87: 1.88 | BV87: 1.96 | BW87: 1.75 | BX87: 2.09 | BY87: 1.88 | BZ87: 4 | CA87: 3.3 | CB87: 2 | CC87: 3.75 | CD87: 3.3 | CE87: 2.05 | CF87: 4 | CG87: 3.3 | CH87: 2 | CI87: 3.9 | CJ87: 3.4 | CK87: 2 | CL87: 3.9 | CM87: 3.25 | CN87: 2 | CO87: 3.9 | CP87: 3.3 | CQ87: 2 | CR87: 3.9 | CS87: 3.3 | CT87: 2 | CU87: 3.98 | CV87: 3.35 | CW87: 2.06 | CX87: 4.2 | CY87: 3.4 | CZ87: 2.05 | DA87: 3.97 | DB87: 3.29 | DC87: 1.99 | DD87: 4.4 | DE87: 3.45 | DF87: 2.04 | DG87: 2.2 | DH87: 1.67 | DI87: 2.16 | DJ87: 1.74 | DK87: 2.22 | DL87: 1.73 | DM87: 2.16 | DN87: 1.66 | DO87: 2.36 | DP87: 1.71 | DQ87: 0.5 | DR87: 1.85 | DS87: 2 | DT87: 1.85 | DU87: 2.07 | DV87: 1.85 | DW87: 2 | DX87: 1.82 | DY87: 1.95 | DZ87: 1.94 | EA87: 2.05
A88: SP1 | B88: 2025-10-19 | C88: 15:14:59.9999999999968050 | D88: Celta | E88: Sociedad | F88: 1 | G88: 1 | H88: D | I88: 1 | J88: 0 | K88: H | L88: 4 | M88: 17 | N88: 1 | O88: 7 | P88: 10 | Q88: 20 | R88: 1 | S88: 10 | T88: 4 | U88: 3 | V88: 1 | W88: 0 | X88: 2.1 | Y88: 3.4 | Z88: 3.5 | AA88: 2.15 | AB88: 3.4 | AC88: 3.4 | AD88: 2.16 | AE88: 3.3 | AF88: 3.45 | AG88: 2.05 | AH88: 3.3 | AI88: 3.3 | AJ88: 2.15 | AK88: 3.4 | AL88: 3.4 | AM88: 2.15 | AN88: 3.4 | AO88: 3.4 | AP88: 2.1 | AQ88: 3.3 | AR88: 3.4 | AS88: 2.11 | AT88: 3.42 | AU88: 3.74 | AV88: 2.16 | AW88: 3.4 | AX88: 3.75 | AY88: 2.1 | AZ88: 3.33 | BA88: 3.46 | BB88: 2.16 | BC88: 3.45 | BD88: 3.9 | BE88: 1.98 | BF88: 1.88 | BG88: 1.96 | BH88: 1.93 | BI88: 1.98 | BJ88: 1.91 | BK88: 1.92 | BL88: 1.83 | BM88: 2 | BN88: 1.94 | BO88: -0.25 | BP88: 1.8 | BQ88: 2.05 | BR88: 1.82 | BS88: 2.11 | BT88: 1.85 | BU88: 2.05 | BV88: 1.8 | BW88: 1.97 | BX88: 1.86 | BY88: 2.12 | BZ88: 1.95 | CA88: 3.5 | CB88: 3.9 | CC88: 2 | CD88: 3.4 | CE88: 3.75 | CF88: 2 | CG88: 3.4 | CH88: 3.85 | CI88: 1.95 | CJ88: 3.5 | CK88: 3.9 | CL88: 2 | CM88: 3.4 | CN88: 3.8 | CO88: 2 | CP88: 3.4 | CQ88: 3.75 | CR88: 2 | CS88: 3.3 | CT88: 3.7 | CU88: 2.18 | CV88: 3.5 | CW88: 3.53 | CX88: 2 | CY88: 3.5 | CZ88: 4 | DA88: 1.98 | DB88: 3.41 | DC88: 3.82 | DD88: 2.08 | DE88: 3.6 | DF88: 4 | DG88: 2.1 | DH88: 1.73 | DI88: 1.9 | DJ88: 2.01 | DK88: 2.1 | DL88: 1.87 | DM88: 1.96 | DN88: 1.81 | DO88: 2.08 | DP88: 1.9 | DQ88: -0.5 | DR88: 1.98 | DS88: 1.88 | DT88: 2.18 | DU88: 1.77 | DV88: 1.98 | DW88: 1.88 | DX88: 1.94 | DY88: 1.83 | DZ88: 2.08 | EA88: 1.9
A89: SP1 | B89: 2025-10-19 | C89: 17:29:59.9999999999968050 | D89: Levante | E89: Vallecano | F89: 0 | G89: 3 | H89: A | I89: 0 | J89: 2 | K89: A | L89: 17 | M89: 10 | N89: 4 | O89: 5 | P89: 6 | Q89: 18 | R89: 11 | S89: 4 | T89: 0 | U89: 1 | V89: 0 | W89: 0 | X89: 2.88 | Y89: 3.25 | Z89: 2.5 | AA89: 2.75 | AB89: 3.3 | AC89: 2.6 | AD89: 2.8 | AE89: 3.35 | AF89: 2.5 | AG89: 2.7 | AH89: 3.25 | AI89: 2.45 | AJ89: 2.7 | AK89: 3.4 | AL89: 2.55 | AM89: 2.7 | AN89: 3.4 | AO89: 2.5 | AP89: 2.7 | AQ89: 3.4 | AR89: 2.5 | AS89: 2.84 | AT89: 3.54 | AU89: 2.51 | AV89: 2.88 | AW89: 3.4 | AX89: 2.6 | AY89: 2.75 | AZ89: 3.33 | BA89: 2.5 | BB89: 2.94 | BC89: 3.5 | BD89: 2.6 | BE89: 1.98 | BF89: 1.88 | BG89: 2.01 | BH89: 1.88 | BI89: 1.98 | BJ89: 1.91 | BK89: 1.91 | BL89: 1.83 | BM89: 2 | BN89: 1.97 | BO89: 0 | BP89: 2.03 | BQ89: 1.83 | BR89: 2.08 | BS89: 1.84 | BT89: 2.03 | BU89: 1.83 | BV89: 1.97 | BW89: 1.79 | BX89: 2.1 | BY89: 1.86 | BZ89: 2.7 | CA89: 3.2 | CB89: 2.7 | CC89: 2.63 | CD89: 3.25 | CE89: 2.75 | CF89: 2.6 | CG89: 3.35 | CH89: 2.7 | CI89: 2.63 | CJ89: 3.3 | CK89: 2.7 | CL89: 2.65 | CM89: 3.25 | CN89: 2.65 | CO89: 2.62 | CP89: 3.25 | CQ89: 2.62 | CR89: 2.62 | CS89: 3.25 | CT89: 2.62 | CU89: 2.86 | CV89: 3.37 | CW89: 2.62 | CX89: 2.71 | CY89: 3.35 | CZ89: 2.8 | DA89: 2.63 | DB89: 3.25 | DC89: 2.69 | DD89: 2.78 | DE89: 3.4 | DF89: 2.86 | DG89: 2 | DH89: 1.8 | DI89: 1.98 | DJ89: 1.93 | DK89: 2.05 | DL89: 1.84 | DM89: 1.96 | DN89: 1.8 | DO89: 2.08 | DP89: 1.89 | DQ89: 0 | DR89: 1.93 | DS89: 1.93 | DT89: 2.05 | DU89: 1.88 | DV89: 1.93 | DW89: 1.95 | DX89: 1.86 | DY89: 1.9 | DZ89: 1.96 | EA89: 2.03
A90: SP1 | B90: 2025-10-19 | C90: 20:00:00.0000000000031950 | D90: Getafe | E90: Real Madrid | F90: 0 | G90: 1 | H90: A | I90: 0 | J90: 0 | K90: D | L90: 7 | M90: 23 | N90: 1 | O90: 10 | P90: 27 | Q90: 11 | R90: 1 | S90: 4 | T90: 4 | U90: 1 | V90: 2 | W90: 0 | X90: 8 | Y90: 4.33 | Z90: 1.42 | AA90: 8.5 | AB90: 4.33 | AC90: 1.4 | AD90: 8.5 | AE90: 4.5 | AF90: 1.41 | AG90: 7.5 | AH90: 4.1 | AI90: 1.4 | AJ90: 7.75 | AK90: 4.5 | AL90: 1.43 | AM90: 7.5 | AN90: 4.5 | AO90: 1.44 | AP90: 7.5 | AQ90: 4.4 | AR90: 1.44 | AS90: 7.03 | AT90: 4.65 | AU90: 1.47 | AV90: 8.5 | AW90: 4.5 | AX90: 1.46 | AY90: 7.63 | AZ90: 4.38 | BA90: 1.42 | BB90: 8.4 | BC90: 4.8 | BD90: 1.46 | BE90: 1.95 | BF90: 1.9 | BG90: 1.97 | BH90: 1.92 | BI90: 1.95 | BJ90: 1.91 | BK90: 1.9 | BL90: 1.84 | BM90: 1.98 | BN90: 1.97 | BO90: 1.25 | BP90: 1.83 | BQ90: 2.03 | BR90: 1.82 | BS90: 2.11 | BT90: 1.86 | BU90: 2.03 | BV90: 1.8 | BW90: 1.96 | BX90: 1.86 | BY90: 2.08 | BZ90: 7 | CA90: 4.5 | CB90: 1.45 | CC90: 7.5 | CD90: 4.2 | CE90: 1.44 | CF90: 7.5 | CG90: 4.6 | CH90: 1.42 | CI90: 7.5 | CJ90: 4.33 | CK90: 1.44 | CL90: 7 | CM90: 4.5 | CN90: 1.46 | CO90: 7 | CP90: 4.5 | CQ90: 1.44 | CR90: 7 | CS90: 4.4 | CT90: 1.44 | CU90: 7.35 | CV90: 4.57 | CW90: 1.46 | CX90: 7.5 | CY90: 4.6 | CZ90: 1.48 | DA90: 7.14 | DB90: 4.42 | DC90: 1.44 | DD90: 9 | DE90: 4.6 | DF90: 1.48 | DG90: 1.98 | DH90: 1.88 | DI90: 1.94 | DJ90: 1.96 | DK90: 1.98 | DL90: 1.91 | DM90: 1.89 | DN90: 1.87 | DO90: 2.04 | DP90: 1.95 | DQ90: 1.25 | DR90: 1.78 | DS90: 2.1 | DT90: 1.82 | DU90: 2.13 | DV90: 1.85 | DW90: 2.1 | DX90: 1.79 | DY90: 2 | DZ90: 1.83 | EA90: 2.19
A91: SP1 | B91: 2025-10-20 | C91: 20:00:00.0000000000031950 | D91: Alaves | E91: Valencia | F91: 0 | G91: 0 | H91: D | I91: 0 | J91: 0 | K91: D | L91: 13 | M91: 5 | N91: 3 | O91: 2 | P91: 13 | Q91: 20 | R91: 7 | S91: 0 | T91: 1 | U91: 2 | V91: 0 | W91: 0 | X91: 2.25 | Y91: 3 | Z91: 3.6 | AA91: 2.3 | AB91: 3.1 | AC91: 3.4 | AD91: 2.3 | AE91: 3.1 | AF91: 3.4 | AG91: 2.2 | AH91: 3 | AI91: 3.3 | AJ91: 2.25 | AK91: 3.1 | AL91: 3.4 | AM91: 2.25 | AN91: 3.1 | AO91: 3.4 | AP91: 2.25 | AQ91: 3.1 | AR91: 3.3 | AS91: 2.28 | AT91: 3.16 | AU91: 3.58 | AV91: 2.3 | AW91: 3.14 | AX91: 3.6 | AY91: 2.25 | AZ91: 3.06 | BA91: 3.4 | BB91: 2.34 | BC91: 3.15 | BD91: 3.7 | BE91: 2.5 | BF91: 1.53 | BG91: 2.5 | BH91: 1.55 | BI91: 2.5 | BJ91: 1.57 | BK91: 2.39 | BL91: 1.54 | BM91: 2.56 | BN91: 1.58 | BO91: -0.25 | BP91: 1.93 | BQ91: 1.93 | BR91: 1.94 | BS91: 1.96 | BT91: 1.94 | BU91: 1.93 | BV91: 1.9 | BW91: 1.87 | BX91: 1.97 | BY91: 2 | BZ91: 2.15 | CA91: 3.1 | CB91: 3.7 | CC91: 2.2 | CD91: 3.2 | CE91: 3.5 | CF91: 2.18 | CG91: 3.1 | CH91: 3.65 | CI91: 2.15 | CJ91: 3.1 | CK91: 3.75 | CL91: 2.2 | CM91: 3.1 | CN91: 3.5 | CO91: 2.2 | CP91: 3.1 | CQ91: 3.5 | CR91: 2.2 | CS91: 3.1 | CT91: 3.5 | CU91: 2.23 | CV91: 3.23 | CW91: 3.7 | CX91: 2.2 | CY91: 3.2 | CZ91: 3.75 | DA91: 2.18 | DB91: 3.11 | DC91: 3.59 | DD91: 2.26 | DE91: 3.25 | DF91: 3.9 | DG91: 2.3 | DH91: 1.62 | DI91: 2.4 | DJ91: 1.62 | DK91: 2.35 | DL91: 1.65 | DM91: 2.28 | DN91: 1.6 | DO91: 2.42 | DP91: 1.69 | DQ91: -0.25 | DR91: 1.83 | DS91: 2.03 | DT91: 1.9 | DU91: 2.02 | DV91: 1.85 | DW91: 2.03 | DX91: 1.82 | DY91: 1.96 | DZ91: 1.93 | EA91: 2.07
A92: SP1 | B92: 2025-10-24 | C92: 20:00:00.0000000000031950 | D92: Sociedad | E92: Sevilla | F92: 2 | G92: 1 | H92: H | I92: 2 | J92: 1 | K92: H | L92: 5 | M92: 6 | N92: 3 | O92: 1 | P92: 19 | Q92: 14 | R92: 1 | S92: 9 | T92: 1 | U92: 3 | V92: 0 | W92: 0 | X92: 1.95 | Y92: 3.5 | Z92: 3.8 | AA92: 2 | AB92: 3.4 | AC92: 3.75 | AD92: 2.02 | AE92: 3.4 | AF92: 3.95 | AG92: 2 | AH92: 3.5 | AI92: 3.7 | AJ92: 2 | AK92: 3.4 | AL92: 3.75 | AM92: 2 | AN92: 3.4 | AO92: 3.8 | AP92: 2 | AQ92: 3.4 | AR92: 3.75 | AS92: 2.03 | AT92: 3.5 | AU92: 4 | AV92: 2.02 | AW92: 3.5 | AX92: 3.95 | AY92: 1.99 | AZ92: 3.42 | BA92: 3.81 | BB92: 2.06 | BC92: 3.6 | BD92: 4.1 | BE92: 1.98 | BF92: 1.88 | BG92: 2.03 | BH92: 1.88 | BI92: 2 | BJ92: 1.9 | BK92: 1.93 | BL92: 1.83 | BM92: 2.06 | BN92: 1.9 | BO92: -0.5 | BP92: 2 | BQ92: 1.85 | BR92: 2.04 | BS92: 1.88 | BT92: 2 | BU92: 1.86 | BV92: 1.95 | BW92: 1.81 | BX92: 2.06 | BY92: 1.91 | BZ92: 1.91 | CA92: 3.5 | CB92: 3.9 | CC92: 2 | CD92: 3.5 | CE92: 3.75 | CF92: 1.92 | CG92: 3.65 | CH92: 3.9 | CI92: 1.95 | CJ92: 3.5 | CK92: 3.9 | CL92: 2 | CM92: 3.4 | CN92: 3.75 | CO92: 2 | CP92: 3.4 | CQ92: 3.8 | CR92: 2 | CS92: 3.4 | CT92: 3.75 | CU92: 1.98 | CV92: 3.62 | CW92: 4.05 | CX92: 2 | CY92: 3.65 | CZ92: 4.2 | DA92: 1.94 | DB92: 3.5 | DC92: 3.88 | DD92: 2.04 | DE92: 3.65 | DF92: 4.2 | DG92: 2 | DH92: 1.85 | DI92: 1.99 | DJ92: 1.92 | DK92: 2 | DL92: 1.91 | DM92: 1.92 | DN92: 1.85 | DO92: 2.02 | DP92: 1.95 | DQ92: -0.5 | DR92: 1.95 | DS92: 1.9 | DT92: 1.99 | DU92: 1.93 | DV92: 1.95 | DW92: 1.93 | DX92: 1.9 | DY92: 1.86 | DZ92: 2.03 | EA92: 1.96
A93: SP1 | B93: 2025-10-25 | C93: 12:59:59.9999999999968050 | D93: Girona | E93: Oviedo | F93: 3 | G93: 3 | H93: D | I93: 0 | J93: 1 | K93: A | L93: 8 | M93: 10 | N93: 6 | O93: 5 | P93: 13 | Q93: 16 | R93: 11 | S93: 4 | T93: 4 | U93: 3 | V93: 0 | W93: 0 | X93: 1.8 | Y93: 3.5 | Z93: 4.75 | AA93: 1.8 | AB93: 3.5 | AC93: 4.6 | AD93: 1.76 | AE93: 3.6 | AF93: 4.8 | AG93: 1.8 | AH93: 3.6 | AI93: 4.6 | AJ93: 1.85 | AK93: 3.5 | AL93: 4.33 | AM93: 1.85 | AN93: 3.5 | AO93: 4.33 | AP93: 1.83 | AQ93: 3.5 | AR93: 4.2 | AS93: 1.81 | AT93: 3.57 | AU93: 4.87 | AV93: 1.85 | AW93: 3.6 | AX93: 4.8 | AY93: 1.8 | AZ93: 3.52 | BA93: 4.6 | BB93: 1.86 | BC93: 3.7 | BD93: 5.2 | BE93: 2 | BF93: 1.8 | BG93: 2.08 | BH93: 1.81 | BI93: 2.1 | BJ93: 1.83 | BK93: 1.99 | BL93: 1.77 | BM93: 2.1 | BN93: 1.86 | BO93: -0.75 | BP93: 2.03 | BQ93: 1.78 | BR93: 2.08 | BS93: 1.84 | BT93: 2.03 | BU93: 1.83 | BV93: 1.98 | BW93: 1.79 | BX93: 2.11 | BY93: 1.87 | BZ93: 1.73 | CA93: 3.6 | CB93: 5.25 | CC93: 1.73 | CD93: 3.6 | CE93: 5 | CF93: 1.74 | CG93: 3.45 | CH93: 5.4 | CI93: 1.73 | CJ93: 3.7 | CK93: 4.8 | CL93: 1.78 | CM93: 3.5 | CN93: 4.75 | CO93: 1.8 | CP93: 3.5 | CQ93: 4.8 | CR93: 1.75 | CS93: 3.5 | CT93: 4.6 | CU93: 1.76 | CV93: 3.74 | CW93: 5.08 | CX93: 1.8 | CY93: 3.75 | CZ93: 5.4 | DA93: 1.74 | DB93: 3.56 | DC93: 4.95 | DD93: 1.8 | DE93: 3.75 | DF93: 5.6 | DG93: 2 | DH93: 1.85 | DI93: 2.03 | DJ93: 1.88 | DK93: 2.07 | DL93: 1.85 | DM93: 2.01 | DN93: 1.77 | DO93: 2.06 | DP93: 1.92 | DQ93: -0.75 | DR93: 1.98 | DS93: 1.88 | DT93: 2 | DU93: 1.93 | DV93: 1.98 | DW93: 1.88 | DX93: 1.93 | DY93: 1.84 | DZ93: 2.04 | EA93: 1.94
A94: SP1 | B94: 2025-10-25 | C94: 15:14:59.9999999999968050 | D94: Espanol | E94: Elche | F94: 1 | G94: 0 | H94: H | I94: 0 | J94: 0 | K94: D | L94: 16 | M94: 13 | N94: 7 | O94: 4 | P94: 14 | Q94: 15 | R94: 4 | S94: 2 | T94: 4 | U94: 2 | V94: 0 | W94: 0 | X94: 1.95 | Y94: 3.25 | Z94: 4.1 | AA94: 2 | AB94: 3.3 | AC94: 4 | AD94: 1.97 | AE94: 3.3 | AF94: 4.1 | AG94: 2 | AH94: 3.4 | AI94: 3.9 | AJ94: 2 | AK94: 3.3 | AL94: 3.75 | AM94: 2.05 | AN94: 3.4 | AO94: 3.75 | AP94: 2 | AQ94: 3.3 | AR94: 3.75 | AS94: 2 | AT94: 3.47 | AU94: 4.06 | AV94: 2.05 | AW94: 3.5 | AX94: 4.2 | AY94: 1.97 | AZ94: 3.34 | BA94: 3.91 | BB94: 2.08 | BC94: 3.45 | BD94: 4.2 | BE94: 2.1 | BF94: 1.73 | BG94: 2.13 | BH94: 1.77 | BI94: 2.1 | BJ94: 1.75 | BK94: 2.07 | BL94: 1.71 | BM94: 2.18 | BN94: 1.8 | BO94: -0.5 | BP94: 1.98 | BQ94: 1.88 | BR94: 2.01 | BS94: 1.9 | BT94: 1.98 | BU94: 1.88 | BV94: 1.94 | BW94: 1.81 | BX94: 2.08 | BY94: 1.9 | BZ94: 2 | CA94: 3.3 | CB94: 4 | CC94: 2 | CD94: 3.4 | CE94: 3.75 | CF94: 1.92 | CG94: 3.4 | CH94: 4.2 | CI94: 2 | CJ94: 3.4 | CK94: 3.9 | CL94: 1.98 | CM94: 3.3 | CN94: 3.9 | CO94: 2 | CP94: 3.3 | CQ94: 3.9 | CR94: 2 | CS94: 3.3 | CT94: 3.9 | CU94: 2.03 | CV94: 3.29 | CW94: 4.31 | CX94: 2 | CY94: 3.4 | CZ94: 4.33 | DA94: 1.97 | DB94: 3.33 | DC94: 3.99 | DD94: 2.06 | DE94: 3.35 | DF94: 4.6 | DG94: 2.1 | DH94: 1.73 | DI94: 2.2 | DJ94: 1.74 | DK94: 2.15 | DL94: 1.73 | DM94: 2.08 | DN94: 1.71 | DO94: 2.2 | DP94: 1.8 | DQ94: -0.5 | DR94: 2 | DS94: 1.85 | DT94: 2.04 | DU94: 1.89 | DV94: 2 | DW94: 1.88 | DX94: 1.92 | DY94: 1.84 | DZ94: 2.06 | EA94: 1.93
A95: SP1 | B95: 2025-10-25 | C95: 17:29:59.9999999999968050 | D95: Ath Bilbao | E95: Getafe | F95: 0 | G95: 1 | H95: A | I95: 0 | J95: 0 | K95: D | L95: 7 | M95: 8 | N95: 4 | O95: 3 | P95: 15 | Q95: 14 | R95: 1 | S95: 5 | T95: 1 | U95: 3 | V95: 0 | W95: 0 | X95: 1.67 | Y95: 3.5 | Z95: 6 | AA95: 1.67 | AB95: 3.4 | AC95: 6.5 | AD95: 1.62 | AE95: 3.65 | AF95: 6.25 | AG95: 1.65 | AH95: 3.4 | AI95: 6.5 | AJ95: 1.65 | AK95: 3.5 | AL95: 6 | AM95: 1.65 | AN95: 3.5 | AO95: 6 | AP95: 1.65 | AQ95: 3.5 | AR95: 5.75 | AS95: 1.68 | AT95: 3.66 | AU95: 5.91 | AV95: 1.69 | AW95: 3.65 | AX95: 6.5 | AY95: 1.65 | AZ95: 3.49 | BA95: 6.08 | BB95: 1.69 | BC95: 3.65 | BD95: 6.8 | BE95: 2.75 | BF95: 1.44 | BG95: 2.72 | BH95: 1.48 | BI95: 2.75 | BJ95: 1.5 | BK95: 2.62 | BL95: 1.45 | BM95: 2.76 | BN95: 1.52 | BO95: -0.75 | BP95: 1.88 | BQ95: 1.98 | BR95: 1.91 | BS95: 2 | BT95: 1.9 | BU95: 1.98 | BV95: 1.83 | BW95: 1.94 | BX95: 1.91 | BY95: 2.04 | BZ95: 1.65 | CA95: 3.5 | CB95: 6 | CC95: 1.67 | CD95: 3.4 | CE95: 6.5 | CF95: 1.58 | CG95: 3.6 | CH95: 7 | CI95: 1.62 | CJ95: 3.5 | CK95: 6.5 | CL95: 1.63 | CM95: 3.5 | CN95: 6.25 | CO95: 1.65 | CP95: 3.5 | CQ95: 6.5 | CR95: 1.61 | CS95: 3.5 | CT95: 6 | CU95: 1.65 | CV95: 3.6 | CW95: 6.65 | CX95: 1.67 | CY95: 3.6 | CZ95: 7.3 | DA95: 1.61 | DB95: 3.5 | DC95: 6.53 | DD95: 1.69 | DE95: 3.65 | DF95: 7.2 | DG95: 2.75 | DH95: 1.44 | DI95: 2.74 | DJ95: 1.49 | DK95: 2.75 | DL95: 1.5 | DM95: 2.66 | DN95: 1.45 | DO95: 2.82 | DP95: 1.53 | DQ95: -0.75 | DR95: 1.85 | DS95: 2 | DT95: 1.88 | DU95: 2.05 | DV95: 1.85 | DW95: 2.08 | DX95: 1.78 | DY95: 2.02 | DZ95: 1.9 | EA95: 2.06
A96: SP1 | B96: 2025-10-25 | C96: 20:00:00.0000000000031950 | D96: Valencia | E96: Villarreal | F96: 0 | G96: 2 | H96: A | I96: 0 | J96: 1 | K96: A | L96: 15 | M96: 12 | N96: 3 | O96: 5 | P96: 13 | Q96: 14 | R96: 7 | S96: 5 | T96: 2 | U96: 4 | V96: 0 | W96: 0 | X96: 3.1 | Y96: 3.6 | Z96: 2.2 | AA96: 3.3 | AB96: 3.4 | AC96: 2.2 | AD96: 3.25 | AE96: 3.4 | AF96: 2.2 | AG96: 3.13 | AH96: 3.5 | AI96: 2.2 | AJ96: 3.1 | AK96: 3.5 | AL96: 2.2 | AM96: 3.1 | AN96: 3.5 | AO96: 2.2 | AP96: 3.1 | AQ96: 3.5 | AR96: 2.2 | AS96: 3.29 | AT96: 3.62 | AU96: 2.2 | AV96: 3.35 | AW96: 3.6 | AX96: 2.2 | AY96: 3.19 | AZ96: 3.47 | BA96: 2.18 | BB96: 3.45 | BC96: 3.65 | BD96: 2.28 | BE96: 1.8 | BF96: 2 | BG96: 1.81 | BH96: 2.09 | BI96: 1.87 | BJ96: 2 | BK96: 1.8 | BL96: 1.94 | BM96: 1.85 | BN96: 2.1 | BO96: 0.25 | BP96: 1.93 | BQ96: 1.93 | BR96: 1.99 | BS96: 1.92 | BT96: 1.95 | BU96: 1.93 | BV96: 1.9 | BW96: 1.82 | BX96: 2.02 | BY96: 1.96 | BZ96: 3.6 | CA96: 3.6 | CB96: 2.05 | CC96: 3.75 | CD96: 3.5 | CE96: 2 | CF96: 3.6 | CG96: 3.55 | CH96: 2.02 | CI96: 3.5 | CJ96: 3.6 | CK96: 2.05 | CL96: 3.5 | CM96: 3.5 | CN96: 2.05 | CO96: 3.5 | CP96: 3.5 | CQ96: 2.05 | CR96: 3.5 | CS96: 3.5 | CT96: 2.05 | CU96: 3.83 | CV96: 3.46 | CW96: 2.09 | CX96: 3.8 | CY96: 3.6 | CZ96: 2.05 | DA96: 3.61 | DB96: 3.49 | DC96: 2.02 | DD96: 3.9 | DE96: 3.55 | DF96: 2.14 | DG96: 1.85 | DH96: 2 | DI96: 1.93 | DJ96: 1.98 | DK96: 1.88 | DL96: 2 | DM96: 1.8 | DN96: 1.96 | DO96: 1.95 | DP96: 2.02 | DQ96: 0.5 | DR96: 1.8 | DS96: 2.05 | DT96: 1.84 | DU96: 2.1 | DV96: 1.85 | DW96: 2.05 | DX96: 1.79 | DY96: 1.98 | DZ96: 1.86 | EA96: 2.14
... A161: SP1 | B161: 2025-12-14 | C161: 20:00:00.0000000000031950 | D161: Alaves | E161: Real Madrid | F161: 1 | G161: 2 | H161: A | I161: 0 | J161: 1 | K161: A | L161: 6 | M161: 13 | N161: 2 | O161: 6 | P161: 12 | Q161: 13 | R161: 5 | S161: 7 | T161: 3 | U161: 1 | V161: 0 | W161: 0 | X161: 5.5 | Y161: 4 | Z161: 1.6 | AA161: 5.5 | AB161: 4 | AC161: 1.6 | AD161: 5.6 | AE161: 4.2 | AF161: 1.58 | AG161: 5 | AH161: 3.9 | AI161: 1.57 | AJ161: 5.25 | AK161: 4 | AL161: 1.62 | AM161: 5.25 | AN161: 4 | AO161: 1.61 | AP161: 5.25 | AQ161: 4 | AR161: 1.61 | AS161: 6 | AT161: 3.88 | AU161: 1.63 | AV161: 5.75 | AW161: 4.2 | AX161: 1.64 | AY161: 5.4 | AZ161: 3.94 | BA161: 1.6 | BB161: 6 | BC161: 4.1 | BD161: 1.65 | BE161: 1.73 | BF161: 2.1 | BG161: 1.79 | BH161: 2.1 | BI161: 1.76 | BJ161: 2.1 | BK161: 1.71 | BL161: 2.05 | BM161: 1.84 | BN161: 2.16 | BO161: 1 | BP161: 1.8 | BQ161: 2.05 | BR161: 1.82 | BS161: 2.11 | BT161: 1.81 | BU161: 2.05 | BV161: 1.78 | BW161: 1.99 | BX161: 1.86 | BY161: 2.1 | BZ161: 5.75 | CA161: 4 | CB161: 1.57 | CC161: 6 | CD161: 4 | CE161: 1.53 | CF161: 6.1 | CG161: 4.1 | CH161: 1.54 | CI161: 5.75 | CJ161: 4.2 | CK161: 1.55 | CL161: 5.5 | CM161: 4 | CN161: 1.6 | CO161: 5.5 | CP161: 4 | CQ161: 1.6 | CR161: 5.5 | CS161: 3.9 | CT161: 1.6 | CU161: 5.73 | CV161: 4.12 | CW161: 1.61 | CX161: 6.1 | CY161: 4.2 | CZ161: 1.62 | DA161: 5.73 | DB161: 4.05 | DC161: 1.56 | DD161: 6.4 | DE161: 4.3 | DF161: 1.62 | DG161: 1.73 | DH161: 2.1 | DI161: 1.79 | DJ161: 2.1 | DK161: 1.8 | DL161: 2.1 | DM161: 1.75 | DN161: 2.02 | DO161: 1.88 | DP161: 2.12 | DQ161: 1 | DR161: 1.88 | DS161: 1.98 | DT161: 1.85 | DU161: 2.08 | DV161: 1.91 | DW161: 2 | DX161: 1.87 | DY161: 1.91 | DZ161: 1.93 | EA161: 2.06
A162: SP1 | B162: 2025-12-15 | C162: 20:00:00.0000000000031950 | D162: Vallecano | E162: Betis | F162: 0 | G162: 0 | H162: D | I162: 0 | J162: 0 | K162: D | L162: 23 | M162: 13 | N162: 7 | O162: 6 | P162: 10 | Q162: 7 | R162: 8 | S162: 3 | T162: 4 | U162: 1 | V162: 0 | W162: 0 | X162: 2.55 | Y162: 3.4 | Z162: 2.75 | AA162: 2.6 | AB162: 3.25 | AC162: 2.75 | AD162: 2.55 | AE162: 3.5 | AF162: 2.7 | AG162: 2.5 | AH162: 3.25 | AI162: 2.6 | AJ162: 2.55 | AK162: 3.4 | AL162: 2.7 | AM162: 2.5 | AN162: 3.4 | AO162: 2.7 | AP162: 2.5 | AQ162: 3.3 | AR162: 2.7 | AS162: 2.65 | AT162: 3.48 | AU162: 2.71 | AV162: 2.6 | AW162: 3.5 | AX162: 2.75 | AY162: 2.52 | AZ162: 3.35 | BA162: 2.69 | BB162: 2.74 | BC162: 3.35 | BD162: 2.8 | BE162: 1.95 | BF162: 1.9 | BG162: 1.98 | BH162: 1.91 | BI162: 1.95 | BJ162: 1.91 | BK162: 1.92 | BL162: 1.83 | BM162: 1.97 | BN162: 1.96 | BO162: 0 | BP162: 1.88 | BQ162: 1.98 | BR162: 1.93 | BS162: 1.97 | BT162: 1.88 | BU162: 1.98 | BV162: 1.82 | BW162: 1.93 | BX162: 1.96 | BY162: 1.98 | BZ162: 2.55 | CA162: 3.2 | CB162: 2.9 | CC162: 2.6 | CD162: 3.1 | CE162: 2.8 | CF162: 2.55 | CG162: 3.15 | CH162: 2.95 | CI162: 2.55 | CJ162: 3.25 | CK162: 2.88 | CL162: 2.55 | CM162: 3.1 | CN162: 2.9 | CX162: 2.6 | CY162: 3.25 | CZ162: 2.95 | DA162: 2.55 | DB162: 3.15 | DC162: 2.88 | DD162: 2.66 | DE162: 3.3 | DF162: 3.05 | DG162: 2.2 | DH162: 1.67 | DI162: 2.24 | DJ162: 1.71 | DK162: 2.2 | DL162: 1.85 | DM162: 2.11 | DN162: 1.69 | DO162: 2.28 | DP162: 1.77 | DQ162: 0 | DR162: 1.8 | DS162: 2.05 | DT162: 1.83 | DU162: 2.11 | DV162: 1.8 | DW162: 2.05 | DX162: 1.77 | DY162: 2.01 | DZ162: 1.86 | EA162: 2.14
A163: SP1 | B163: 2025-12-19 | C163: 20:00:00.0000000000031950 | D163: Valencia | E163: Mallorca | F163: 1 | G163: 1 | H163: D | I163: 0 | J163: 1 | K163: A | L163: 17 | M163: 4 | N163: 2 | O163: 2 | P163: 10 | Q163: 12 | R163: 12 | S163: 3 | T163: 2 | U163: 3 | V163: 0 | W163: 0 | X163: 1.9 | Y163: 3 | Z163: 4 | AA163: 1.95 | AB163: 3.2 | AC163: 4.2 | AD163: 1.98 | AE163: 3.25 | AF163: 4.1 | AG163: 2 | AH163: 3.25 | AI163: 4.1 | AJ163: 1.98 | AK163: 3.2 | AL163: 4.1 | AM163: 2 | AN163: 3.25 | AO163: 4 | AP163: 2 | AQ163: 3.2 | AR163: 4 | AS163: 2.04 | AT163: 3.3 | AU163: 4.26 | AV163: 2.05 | AW163: 3.25 | AX163: 4.2 | AY163: 1.98 | AZ163: 3.19 | BA163: 4.08 | BB163: 2.08 | BC163: 3.4 | BD163: 4.4 | BE163: 2.38 | BF163: 1.57 | BG163: 2.5 | BH163: 1.56 | BI163: 2.48 | BJ163: 1.57 | BK163: 2.4 | BL163: 1.54 | BM163: 2.52 | BN163: 1.64 | BO163: -0.5 | BP163: 2 | BQ163: 1.85 | BR163: 2.04 | BS163: 1.88 | BT163: 2 | BU163: 1.85 | BV163: 1.93 | BW163: 1.8 | BX163: 2.08 | BY163: 1.91 | BZ163: 2.05 | CA163: 3.2 | CB163: 3.8 | CC163: 2.05 | CD163: 3.1 | CE163: 4 | CF163: 1.96 | CG163: 3.25 | CH163: 4.25 | CI163: 2.05 | CJ163: 3.2 | CK163: 3.9 | CL163: 2.05 | CM163: 3.2 | CN163: 3.9 | CO163: 2.05 | CP163: 3.2 | CQ163: 3.9 | CR163: 2.05 | CS163: 3.1 | CT163: 3.9 | CU163: 2.11 | CV163: 3.22 | CW163: 4.08 | CX163: 2.06 | CY163: 3.25 | CZ163: 4.25 | DA163: 2.03 | DB163: 3.17 | DC163: 3.96 | DD163: 2.14 | DE163: 3.25 | DF163: 4.3 | DG163: 2.38 | DH163: 1.57 | DI163: 2.46 | DJ163: 1.58 | DK163: 2.45 | DL163: 1.58 | DM163: 2.37 | DN163: 1.55 | DO163: 2.5 | DP163: 1.64 | DQ163: -0.5 | DR163: 2.1 | DS163: 1.78 | DT163: 2.12 | DU163: 1.82 | DV163: 2.1 | DW163: 1.78 | DX163: 2.02 | DY163: 1.74 | DZ163: 2.14 | EA163: 1.86
A164: SP1 | B164: 2025-12-20 | C164: 12:59:59.9999999999968050 | D164: Oviedo | E164: Celta | F164: 0 | G164: 0 | H164: D | I164: 0 | J164: 0 | K164: D | L164: 10 | M164: 6 | N164: 3 | O164: 2 | P164: 14 | Q164: 7 | R164: 4 | S164: 3 | T164: 2 | U164: 1 | V164: 0 | W164: 0 | X164: 3.6 | Y164: 3.4 | Z164: 2.05 | AA164: 3.75 | AB164: 3.2 | AC164: 2.05 | AD164: 3.9 | AE164: 3.25 | AF164: 2.04 | AG164: 3.7 | AH164: 3.3 | AI164: 2.1 | AJ164: 3.6 | AK164: 3.3 | AL164: 2.1 | AM164: 3.6 | AN164: 3.3 | AO164: 2.1 | AP164: 3.6 | AQ164: 3.3 | AR164: 2.1 | AS164: 3.81 | AT164: 3.39 | AU164: 2.1 | AV164: 3.9 | AW164: 3.4 | AX164: 2.1 | AY164: 3.7 | AZ164: 3.27 | BA164: 2.07 | BB164: 3.9 | BC164: 3.5 | BD164: 2.16 | BE164: 2.2 | BF164: 1.67 | BG164: 2.34 | BH164: 1.65 | BI164: 2.32 | BJ164: 1.67 | BK164: 2.21 | BL164: 1.62 | BM164: 2.38 | BN164: 1.7 | BO164: 0.5 | BP164: 1.8 | BQ164: 2.05 | BR164: 1.82 | BS164: 2.11 | BT164: 1.83 | BU164: 2.05 | BV164: 1.74 | BW164: 2.01 | BX164: 1.84 | BY164: 2.16 | BZ164: 3.4 | CA164: 3.2 | CB164: 2.2 | CC164: 3.6 | CD164: 3.1 | CE164: 2.15 | CF164: 3.65 | CG164: 3.25 | CH164: 2.12 | CI164: 3.5 | CJ164: 3.2 | CK164: 2.2 | CL164: 3.4 | CM164: 3.2 | CN164: 2.2 | CO164: 3.4 | CP164: 3.2 | CQ164: 2.2 | CR164: 3.4 | CS164: 3.2 | CT164: 2.2 | CU164: 3.6 | CV164: 3.26 | CW164: 2.26 | CX164: 3.65 | CY164: 3.33 | CZ164: 2.25 | DA164: 3.47 | DB164: 3.18 | DC164: 2.18 | DD164: 3.8 | DE164: 3.25 | DF164: 2.3 | DG164: 2.5 | DH164: 1.53 | DI164: 2.45 | DJ164: 1.61 | DK164: 2.5 | DL164: 1.6 | DM164: 2.34 | DN164: 1.56 | DO164: 2.52 | DP164: 1.63 | DQ164: 0.25 | DR164: 1.95 | DS164: 1.9 | DT164: 2 | DU164: 1.93 | DV164: 2 | DW164: 1.9 | DX164: 1.94 | DY164: 1.78 | DZ164: 2.02 | EA164: 1.95
A165: SP1 | B165: 2025-12-20 | C165: 15:14:59.9999999999968050 | D165: Levante | E165: Sociedad | F165: 1 | G165: 1 | H165: D | I165: 0 | J165: 1 | K165: A | L165: 13 | M165: 18 | N165: 3 | O165: 6 | P165: 16 | Q165: 13 | R165: 7 | S165: 10 | T165: 6 | U165: 2 | V165: 0 | W165: 0 | X165: 3.4 | Y165: 3.4 | Z165: 2.15 | AA165: 3.4 | AB165: 3.4 | AC165: 2.1 | AD165: 3.25 | AE165: 3.45 | AF165: 2.18 | AG165: 3.3 | AH165: 3.5 | AI165: 2.15 | AJ165: 3.2 | AK165: 3.4 | AL165: 2.2 | AM165: 3.2 | AN165: 3.4 | AO165: 2.2 | AP165: 3.2 | AQ165: 3.4 | AR165: 2.2 | AS165: 3.47 | AT165: 3.53 | AU165: 2.16 | AV165: 3.4 | AW165: 3.5 | AX165: 2.2 | AY165: 3.29 | AZ165: 3.41 | BA165: 2.15 | BB165: 3.55 | BC165: 3.6 | BD165: 2.24 | BE165: 1.93 | BF165: 1.93 | BG165: 1.94 | BH165: 1.94 | BI165: 1.93 | BJ165: 1.93 | BK165: 1.87 | BL165: 1.86 | BM165: 1.98 | BN165: 1.98 | BO165: 0.25 | BP165: 2 | BQ165: 1.85 | BR165: 2.03 | BS165: 1.88 | BT165: 2 | BU165: 1.88 | BV165: 1.93 | BW165: 1.8 | BX165: 2.05 | BY165: 1.93 | BZ165: 3 | CA165: 3.3 | CB165: 2.38 | CC165: 3 | CD165: 3.2 | CE165: 2.38 | CF165: 3.1 | CG165: 3.3 | CH165: 2.35 | CI165: 3 | CJ165: 3.3 | CK165: 2.38 | CL165: 2.9 | CM165: 3.3 | CN165: 2.4 | CO165: 2.9 | CP165: 3.3 | CQ165: 2.45 | CR165: 2.9 | CS165: 3.25 | CT165: 2.4 | CU165: 3.18 | CV165: 3.38 | CW165: 2.4 | CX165: 3.1 | CY165: 3.33 | CZ165: 2.45 | DA165: 3 | DB165: 3.26 | DC165: 2.38 | DD165: 3.25 | DE165: 3.4 | DF165: 2.5 | DG165: 2 | DH165: 1.8 | DI165: 2.11 | DJ165: 1.8 | DK165: 2.1 | DL165: 1.8 | DM165: 2.03 | DN165: 1.75 | DO165: 2.14 | DP165: 1.87 | DQ165: 0.25 | DR165: 1.8 | DS165: 2.05 | DT165: 1.87 | DU165: 2.07 | DV165: 1.81 | DW165: 2.05 | DX165: 1.78 | DY165: 1.94 | DZ165: 1.87 | EA165: 2.13
A166: SP1 | B166: 2025-12-20 | C166: 17:29:59.9999999999968050 | D166: Osasuna | E166: Alaves | F166: 3 | G166: 0 | H166: H | I166: 0 | J166: 0 | K166: D | L166: 16 | M166: 7 | N166: 7 | O166: 3 | P166: 16 | Q166: 11 | R166: 9 | S166: 0 | T166: 2 | U166: 2 | V166: 0 | W166: 0 | X166: 2.2 | Y166: 3 | Z166: 3.7 | AA166: 2.25 | AB166: 3 | AC166: 3.5 | AD166: 2.28 | AE166: 3.05 | AF166: 3.55 | AG166: 2.2 | AH166: 3.1 | AI166: 3.6 | AJ166: 2.2 | AK166: 3 | AL166: 3.6 | AM166: 2.25 | AN166: 3 | AO166: 3.6 | AP166: 2.2 | AQ166: 3 | AR166: 3.6 | AS166: 2.23 | AT166: 3.12 | AU166: 3.78 | AV166: 2.28 | AW166: 3.1 | AX166: 3.7 | AY166: 2.22 | AZ166: 3.02 | BA166: 3.57 | BB166: 2.32 | BC166: 3.15 | BD166: 3.95 | BE166: 2.63 | BF166: 1.5 | BG166: 2.65 | BH166: 1.5 | BI166: 2.63 | BJ166: 1.53 | BK166: 2.52 | BL166: 1.49 | BM166: 2.72 | BN166: 1.55 | BO166: -0.25 | BP166: 1.88 | BQ166: 1.98 | BR166: 1.89 | BS166: 2.01 | BT166: 1.91 | BU166: 1.98 | BV166: 1.87 | BW166: 1.91 | BX166: 1.95 | BY166: 2.04 | BZ166: 2.2 | CA166: 2.88 | CB166: 4 | CC166: 2.25 | CD166: 2.88 | CE166: 3.75 | CF166: 2.2 | CG166: 2.88 | CH166: 3.95 | CI166: 2.2 | CJ166: 3 | CK166: 3.75 | CL166: 2.2 | CM166: 2.9 | CN166: 3.8 | CO166: 2.2 | CP166: 2.9 | CQ166: 3.8 | CR166: 2.2 | CS166: 2.9 | CT166: 3.8 | CU166: 2.23 | CV166: 3.04 | CW166: 3.97 | CX166: 2.26 | CY166: 3 | CZ166: 4 | DA166: 2.2 | DB166: 2.91 | DC166: 3.82 | DD166: 2.32 | DE166: 3.05 | DF166: 4.1 | DG166: 3.2 | DH166: 1.36 | DI166: 3.06 | DJ166: 1.4 | DK166: 3.2 | DL166: 1.4 | DM166: 2.93 | DN166: 1.38 | DO166: 3.1 | DP166: 1.45 | DQ166: -0.25 | DR166: 1.85 | DS166: 2 | DT166: 1.88 | DU166: 2.04 | DV166: 1.85 | DW166: 2 | DX166: 1.83 | DY166: 1.95 | DZ166: 1.92 | EA166: 2.06
A167: SP1 | B167: 2025-12-20 | C167: 20:00:00.0000000000031950 | D167: Real Madrid | E167: Sevilla | F167: 2 | G167: 0 | H167: H | I167: 1 | J167: 0 | K167: H | L167: 18 | M167: 14 | N167: 8 | O167: 5 | P167: 13 | Q167: 19 | R167: 6 | S167: 5 | T167: 2 | U167: 5 | V167: 0 | W167: 1 | X167: 1.2 | Y167: 7 | Z167: 12 | AA167: 1.2 | AB167: 7 | AC167: 12 | AD167: 1.19 | AE167: 7 | AF167: 14 | AG167: 1.2 | AH167: 7 | AI167: 13 | AJ167: 1.24 | AK167: 6.5 | AL167: 11 | AM167: 1.25 | AN167: 6.5 | AO167: 11 | AP167: 1.25 | AQ167: 6.5 | AR167: 11 | AS167: 1.21 | AT167: 7.03 | AU167: 13.82 | AV167: 1.25 | AW167: 7.5 | AX167: 14 | AY167: 1.21 | AZ167: 6.82 | BA167: 12.31 | BB167: 1.24 | BC167: 7.8 | BD167: 14.5 | BE167: 1.36 | BF167: 3.2 | BG167: 1.36 | BH167: 3.17 | BI167: 1.36 | BJ167: 3.25 | BK167: 1.34 | BL167: 3.11 | BM167: 1.38 | BN167: 3.5 | BO167: -2 | BP167: 1.98 | BQ167: 1.88 | BR167: 1.96 | BS167: 1.93 | BT167: 1.98 | BU167: 1.98 | BV167: 1.87 | BW167: 1.9 | BX167: 2 | BY167: 1.95 | BZ167: 1.2 | CA167: 7.5 | CB167: 13 | CC167: 1.18 | CD167: 7 | CE167: 13 | CF167: 1.17 | CG167: 7.5 | CH167: 15 | CI167: 1.18 | CJ167: 7.5 | CK167: 13 | CL167: 1.21 | CM167: 7.5 | CN167: 11.5 | CO167: 1.2 | CP167: 7.5 | CQ167: 11 | CR167: 1.2 | CS167: 7.5 | CT167: 11 | CU167: 1.21 | CV167: 7.06 | CW167: 13.73 | CX167: 1.22 | CY167: 7.5 | CZ167: 15 | DA167: 1.19 | DB167: 7.14 | DC167: 12.64 | DD167: 1.22 | DE167: 8.4 | DF167: 15 | DG167: 1.4 | DH167: 3 | DI167: 1.41 | DJ167: 2.97 | DK167: 1.4 | DL167: 3.15 | DM167: 1.36 | DN167: 3.02 | DO167: 1.43 | DP167: 3.25 | DQ167: -2 | DR167: 1.9 | DS167: 1.95 | DT167: 1.93 | DU167: 1.97 | DV167: 1.9 | DW167: 2 | DX167: 1.86 | DY167: 1.92 | DZ167: 1.96 | EA167: 2.02
A168: SP1 | B168: 2025-12-21 | C168: 12:59:59.9999999999968050 | D168: Girona | E168: Ath Madrid | F168: 0 | G168: 3 | H168: A | I168: 0 | J168: 2 | K168: A | L168: 9 | M168: 14 | N168: 2 | O168: 6 | P168: 7 | Q168: 14 | R168: 3 | S168: 4 | T168: 2 | U168: 0 | V168: 0 | W168: 0 | X168: 5 | Y168: 4 | Z168: 1.67 | AA168: 5 | AB168: 3.75 | AC168: 1.67 | AD168: 5 | AE168: 4.25 | AF168: 1.62 | AG168: 4.75 | AH168: 3.8 | AI168: 1.62 | AJ168: 4.5 | AK168: 4.1 | AL168: 1.7 | AM168: 4.5 | AN168: 4 | AO168: 1.7 | AP168: 4.4 | AQ168: 4 | AR168: 1.7 | AS168: 4.93 | AT168: 4.18 | AU168: 1.68 | AV168: 5 | AW168: 4.25 | AX168: 1.7 | AY168: 4.79 | AZ168: 4.01 | BA168: 1.65 | BB168: 5.2 | BC168: 4.2 | BD168: 1.74 | BE168: 1.73 | BF168: 2.1 | BG168: 1.78 | BH168: 2.11 | BI168: 1.8 | BJ168: 2.1 | BK168: 1.73 | BL168: 2.03 | BM168: 1.82 | BN168: 2.16 | BO168: 0.75 | BP168: 1.98 | BQ168: 1.88 | BR168: 2.01 | BS168: 1.9 | BT168: 2.02 | BU168: 1.88 | BV168: 1.97 | BW168: 1.79 | BX168: 2.02 | BY168: 1.94 | BZ168: 5 | CA168: 3.8 | CB168: 1.7 | CC168: 4.6 | CD168: 3.75 | CE168: 1.73 | CF168: 5 | CG168: 3.8 | CH168: 1.7 | CI168: 4.8 | CJ168: 3.9 | CK168: 1.7 | CL168: 4.6 | CM168: 3.8 | CN168: 1.73 | CO168: 4.6 | CP168: 3.8 | CQ168: 1.73 | CR168: 4.5 | CS168: 3.75 | CT168: 1.73 | CU168: 4.97 | CV168: 3.77 | CW168: 1.76 | CX168: 5 | CY168: 3.9 | CZ168: 1.73 | DA168: 4.76 | DB168: 3.76 | DC168: 1.71 | DD168: 5.5 | DE168: 3.9 | DF168: 1.77 | DG168: 1.85 | DH168: 2 | DI168: 1.94 | DJ168: 1.96 | DK168: 1.88 | DL168: 2 | DM168: 1.8 | DN168: 1.95 | DO168: 1.93 | DP168: 2.06 | DQ168: 0.75 | DR168: 1.93 | DS168: 1.93 | DT168: 1.93 | DU168: 2 | DV168: 1.93 | DW168: 1.93 | DX168: 1.89 | DY168: 1.88 | DZ168: 1.98 | EA168: 2
A169: SP1 | B169: 2025-12-21 | C169: 15:14:59.9999999999968050 | D169: Villarreal | E169: Barcelona | F169: 0 | G169: 2 | H169: A | I169: 0 | J169: 1 | K169: A | L169: 14 | M169: 19 | N169: 5 | O169: 5 | P169: 10 | Q169: 8 | R169: 5 | S169: 10 | T169: 1 | U169: 1 | V169: 1 | W169: 0 | X169: 3.4 | Y169: 4.75 | Z169: 1.83 | AA169: 3.6 | AB169: 4.33 | AC169: 1.8 | AD169: 3.3 | AE169: 4.6 | AF169: 1.88 | AG169: 3.5 | AH169: 4.2 | AI169: 1.75 | AJ169: 3.3 | AK169: 4.6 | AL169: 1.85 | AM169: 3.3 | AN169: 4.6 | AO169: 1.85 | AP169: 3.3 | AQ169: 4.6 | AR169: 1.83 | AS169: 3.54 | AT169: 4.86 | AU169: 1.83 | AV169: 3.6 | AW169: 5 | AX169: 1.88 | AY169: 3.39 | AZ169: 4.53 | BA169: 1.82 | BB169: 3.75 | BC169: 4.9 | BD169: 1.86 | BE169: 1.29 | BF169: 3.75 | BG169: 1.32 | BH169: 3.35 | BI169: 1.29 | BJ169: 3.85 | BK169: 1.26 | BL169: 3.66 | BM169: 1.3 | BN169: 4 | BO169: 0.75 | BP169: 1.8 | BQ169: 2 | BR169: 1.86 | BS169: 2.06 | BT169: 1.8 | BU169: 2.08 | BV169: 1.76 | BW169: 2.01 | BX169: 1.91 | BY169: 2.07 | BZ169: 3.8 | CA169: 4.33 | CB169: 1.73 | CC169: 4 | CD169: 4.2 | CE169: 1.73 | CF169: 3.95 | CG169: 4.4 | CH169: 1.74 | CI169: 4 | CJ169: 4.4 | CK169: 1.73 | CL169: 3.75 | CM169: 4.4 | CN169: 1.78 | CO169: 3.75 | CP169: 4.4 | CQ169: 1.8 | CR169: 3.7 | CS169: 4.33 | CT169: 1.75 | CU169: 4.19 | CV169: 4.48 | CW169: 1.75 | CX169: 4.1 | CY169: 4.5 | CZ169: 1.8 | DA169: 3.92 | DB169: 4.36 | DC169: 1.73 | DD169: 4.3 | DE169: 4.5 | DF169: 1.82 | DG169: 1.36 | DH169: 3.2 | DI169: 1.37 | DJ169: 3.21 | DK169: 1.36 | DL169: 3.33 | DM169: 1.33 | DN169: 3.19 | DO169: 1.37 | DP169: 3.6 | DQ169: 0.75 | DR169: 1.9 | DS169: 1.95 | DT169: 1.98 | DU169: 1.94 | DV169: 1.93 | DW169: 1.95 | DX169: 1.88 | DY169: 1.88 | DZ169: 1.95 | EA169: 2.03
A170: SP1 | B170: 2025-12-21 | C170: 17:29:59.9999999999968050 | D170: Elche | E170: Vallecano | F170: 4 | G170: 0 | H170: H | I170: 1 | J170: 0 | K170: H | L170: 18 | M170: 18 | N170: 6 | O170: 8 | P170: 15 | Q170: 11 | R170: 4 | S170: 5 | T170: 2 | U170: 3 | V170: 0 | W170: 0 | X170: 2.4 | Y170: 3.1 | Z170: 3.2 | AA170: 2.5 | AB170: 3 | AC170: 3 | AD170: 2.5 | AE170: 3.15 | AF170: 3 | AG170: 2.38 | AH170: 3 | AI170: 2.9 | AJ170: 2.45 | AK170: 3.1 | AL170: 3 | AM170: 2.45 | AN170: 3.1 | AO170: 3 | AP170: 2.45 | AQ170: 3.1 | AR170: 3 | AS170: 2.48 | AT170: 3.08 | AU170: 3.27 | AV170: 2.5 | AW170: 3.15 | AX170: 3.25 | AY170: 2.44 | AZ170: 3.05 | BA170: 3.05 | BB170: 2.5 | BC170: 3.2 | BD170: 3.3 | BE170: 2.38 | BF170: 1.57 | BG170: 2.45 | BH170: 1.57 | BI170: 2.4 | BJ170: 1.6 | BK170: 2.3 | BL170: 1.57 | BM170: 2.46 | BN170: 1.65 | BO170: -0.25 | BP170: 2.05 | BQ170: 1.8 | BR170: 2.11 | BS170: 1.82 | BT170: 2.1 | BU170: 1.8 | BV170: 2.05 | BW170: 1.73 | BX170: 2.12 | BY170: 1.85 | BZ170: 2.5 | CA170: 2.9 | CB170: 3.2 | CC170: 2.5 | CD170: 3 | CE170: 3.1 | CF170: 2.5 | CG170: 3 | CH170: 3.1 | CI170: 2.5 | CJ170: 2.9 | CK170: 3.25 | CL170: 2.45 | CM170: 2.95 | CN170: 3.2 | CO170: 2.45 | CP170: 3 | CQ170: 3.2 | CR170: 2.45 | CS170: 2.9 | CT170: 3.1 | CU170: 2.56 | CV170: 2.99 | CW170: 3.31 | CX170: 2.54 | CY170: 3 | CZ170: 3.25 | DA170: 2.48 | DB170: 2.94 | DC170: 3.15 | DD170: 2.62 | DE170: 3.05 | DF170: 3.4 | DG170: 2.63 | DH170: 1.5 | DI170: 2.68 | DJ170: 1.5 | DK170: 2.63 | DL170: 1.53 | DM170: 2.52 | DN170: 1.5 | DO170: 2.76 | DP170: 1.55 | DQ170: -0.25 | DR170: 2.13 | DS170: 1.75 | DT170: 2.16 | DU170: 1.8 | DV170: 2.13 | DW170: 1.75 | DX170: 2.07 | DY170: 1.73 | DZ170: 2.17 | EA170: 1.83
